[2024-06-20 19:32:27,741] {taskinstance.py:1037} INFO - Dependencies all met for <TaskInstance: text_processing_dag_2.process_text manual__2024-06-20T19:32:12.943832+00:00 [queued]>
[2024-06-20 19:32:27,768] {taskinstance.py:1037} INFO - Dependencies all met for <TaskInstance: text_processing_dag_2.process_text manual__2024-06-20T19:32:12.943832+00:00 [queued]>
[2024-06-20 19:32:27,768] {taskinstance.py:1243} INFO - 
--------------------------------------------------------------------------------
[2024-06-20 19:32:27,768] {taskinstance.py:1244} INFO - Starting attempt 1 of 2
[2024-06-20 19:32:27,768] {taskinstance.py:1245} INFO - 
--------------------------------------------------------------------------------
[2024-06-20 19:32:27,784] {taskinstance.py:1264} INFO - Executing <Task(PythonOperator): process_text> on 2024-06-20 19:32:12.943832+00:00
[2024-06-20 19:32:27,790] {standard_task_runner.py:52} INFO - Started process 252 to run task
[2024-06-20 19:32:27,810] {standard_task_runner.py:76} INFO - Running: ['airflow', 'tasks', 'run', 'text_processing_dag_2', 'process_text', 'manual__2024-06-20T19:32:12.943832+00:00', '--job-id', '18', '--raw', '--subdir', 'DAGS_FOLDER/dag_text_processing_2.py', '--cfg-path', '/tmp/tmp_bs0bbc9', '--error-file', '/tmp/tmpr9ibcrvq']
[2024-06-20 19:32:27,814] {standard_task_runner.py:77} INFO - Job 18: Subtask process_text
[2024-06-20 19:32:27,917] {logging_mixin.py:109} INFO - Running <TaskInstance: text_processing_dag_2.process_text manual__2024-06-20T19:32:12.943832+00:00 [running]> on host 09fa9687a8d2
[2024-06-20 19:32:28,042] {taskinstance.py:1431} INFO - Exporting the following env vars:
AIRFLOW_CTX_DAG_OWNER=airflow
AIRFLOW_CTX_DAG_ID=text_processing_dag_2
AIRFLOW_CTX_TASK_ID=process_text
AIRFLOW_CTX_EXECUTION_DATE=2024-06-20T19:32:12.943832+00:00
AIRFLOW_CTX_DAG_RUN_ID=manual__2024-06-20T19:32:12.943832+00:00
[2024-06-20 19:32:31,678] {taskinstance.py:1718} ERROR - Task failed with exception
Traceback (most recent call last):
  File "/home/airflow/.local/lib/python3.6/site-packages/airflow/models/taskinstance.py", line 1334, in _run_raw_task
    self._execute_task_with_callbacks(context)
  File "/home/airflow/.local/lib/python3.6/site-packages/airflow/models/taskinstance.py", line 1460, in _execute_task_with_callbacks
    result = self._execute_task(context, self.task)
  File "/home/airflow/.local/lib/python3.6/site-packages/airflow/models/taskinstance.py", line 1516, in _execute_task
    result = execute_callable(context=context)
  File "/home/airflow/.local/lib/python3.6/site-packages/airflow/operators/python.py", line 174, in execute
    return_value = self.execute_callable()
  File "/home/airflow/.local/lib/python3.6/site-packages/airflow/operators/python.py", line 188, in execute_callable
    return self.python_callable(*self.op_args, **self.op_kwargs)
  File "/opt/airflow/dags/../scripts/text_processing.py", line 16, in process_text
    nlp = spacy.load("en_core_web_sm")
  File "/home/airflow/.local/lib/python3.6/site-packages/spacy/__init__.py", line 57, in load
    config=config,
  File "/home/airflow/.local/lib/python3.6/site-packages/spacy/util.py", line 472, in load_model
    raise IOError(Errors.E050.format(name=name))
OSError: [E050] Can't find model 'en_core_web_sm'. It doesn't seem to be a Python package or a valid path to a data directory.
[2024-06-20 19:32:31,704] {taskinstance.py:1282} INFO - Marking task as UP_FOR_RETRY. dag_id=text_processing_dag_2, task_id=process_text, execution_date=20240620T193212, start_date=20240620T193227, end_date=20240620T193231
[2024-06-20 19:32:31,760] {standard_task_runner.py:92} ERROR - Failed to execute job 18 for task process_text
Traceback (most recent call last):
  File "/home/airflow/.local/lib/python3.6/site-packages/airflow/task/task_runner/standard_task_runner.py", line 85, in _start_by_fork
    args.func(args, dag=self.dag)
  File "/home/airflow/.local/lib/python3.6/site-packages/airflow/cli/cli_parser.py", line 48, in command
    return func(*args, **kwargs)
  File "/home/airflow/.local/lib/python3.6/site-packages/airflow/utils/cli.py", line 92, in wrapper
    return f(*args, **kwargs)
  File "/home/airflow/.local/lib/python3.6/site-packages/airflow/cli/commands/task_command.py", line 298, in task_run
    _run_task_by_selected_method(args, dag, ti)
  File "/home/airflow/.local/lib/python3.6/site-packages/airflow/cli/commands/task_command.py", line 107, in _run_task_by_selected_method
    _run_raw_task(args, ti)
  File "/home/airflow/.local/lib/python3.6/site-packages/airflow/cli/commands/task_command.py", line 184, in _run_raw_task
    error_file=args.error_file,
  File "/home/airflow/.local/lib/python3.6/site-packages/airflow/utils/session.py", line 70, in wrapper
    return func(*args, session=session, **kwargs)
  File "/home/airflow/.local/lib/python3.6/site-packages/airflow/models/taskinstance.py", line 1334, in _run_raw_task
    self._execute_task_with_callbacks(context)
  File "/home/airflow/.local/lib/python3.6/site-packages/airflow/models/taskinstance.py", line 1460, in _execute_task_with_callbacks
    result = self._execute_task(context, self.task)
  File "/home/airflow/.local/lib/python3.6/site-packages/airflow/models/taskinstance.py", line 1516, in _execute_task
    result = execute_callable(context=context)
  File "/home/airflow/.local/lib/python3.6/site-packages/airflow/operators/python.py", line 174, in execute
    return_value = self.execute_callable()
  File "/home/airflow/.local/lib/python3.6/site-packages/airflow/operators/python.py", line 188, in execute_callable
    return self.python_callable(*self.op_args, **self.op_kwargs)
  File "/opt/airflow/dags/../scripts/text_processing.py", line 16, in process_text
    nlp = spacy.load("en_core_web_sm")
  File "/home/airflow/.local/lib/python3.6/site-packages/spacy/__init__.py", line 57, in load
    config=config,
  File "/home/airflow/.local/lib/python3.6/site-packages/spacy/util.py", line 472, in load_model
    raise IOError(Errors.E050.format(name=name))
OSError: [E050] Can't find model 'en_core_web_sm'. It doesn't seem to be a Python package or a valid path to a data directory.
[2024-06-20 19:32:31,769] {local_task_job.py:154} INFO - Task exited with return code 1
[2024-06-20 19:32:31,833] {local_task_job.py:264} INFO - 0 downstream tasks scheduled from follow-on schedule check
