[2024-06-26 16:35:04,899] {taskinstance.py:1037} INFO - Dependencies all met for <TaskInstance: kafka_consumer_dag.run_kafka_consumer scheduled__2023-01-01T05:25:00+00:00 [queued]>
[2024-06-26 16:35:04,909] {taskinstance.py:1037} INFO - Dependencies all met for <TaskInstance: kafka_consumer_dag.run_kafka_consumer scheduled__2023-01-01T05:25:00+00:00 [queued]>
[2024-06-26 16:35:04,909] {taskinstance.py:1243} INFO - 
--------------------------------------------------------------------------------
[2024-06-26 16:35:04,909] {taskinstance.py:1244} INFO - Starting attempt 1 of 2
[2024-06-26 16:35:04,909] {taskinstance.py:1245} INFO - 
--------------------------------------------------------------------------------
[2024-06-26 16:35:04,924] {taskinstance.py:1264} INFO - Executing <Task(PythonOperator): run_kafka_consumer> on 2023-01-01 05:25:00+00:00
[2024-06-26 16:35:04,928] {standard_task_runner.py:52} INFO - Started process 12515 to run task
[2024-06-26 16:35:04,930] {standard_task_runner.py:76} INFO - Running: ['airflow', 'tasks', 'run', 'kafka_consumer_dag', 'run_kafka_consumer', 'scheduled__2023-01-01T05:25:00+00:00', '--job-id', '3127', '--raw', '--subdir', 'DAGS_FOLDER/kafka_consumer_dag.py', '--cfg-path', '/tmp/tmpza7jngm2', '--error-file', '/tmp/tmpdnr004vd']
[2024-06-26 16:35:04,933] {standard_task_runner.py:77} INFO - Job 3127: Subtask run_kafka_consumer
[2024-06-26 16:35:04,997] {logging_mixin.py:109} INFO - Running <TaskInstance: kafka_consumer_dag.run_kafka_consumer scheduled__2023-01-01T05:25:00+00:00 [running]> on host 1f86a07ac7e4
[2024-06-26 16:35:05,099] {taskinstance.py:1431} INFO - Exporting the following env vars:
AIRFLOW_CTX_DAG_OWNER=airflow
AIRFLOW_CTX_DAG_ID=kafka_consumer_dag
AIRFLOW_CTX_TASK_ID=run_kafka_consumer
AIRFLOW_CTX_EXECUTION_DATE=2023-01-01T05:25:00+00:00
AIRFLOW_CTX_DAG_RUN_ID=scheduled__2023-01-01T05:25:00+00:00
[2024-06-26 16:35:05,104] {taskinstance.py:1718} ERROR - Task failed with exception
Traceback (most recent call last):
  File "/home/airflow/.local/lib/python3.6/site-packages/airflow/models/taskinstance.py", line 1334, in _run_raw_task
    self._execute_task_with_callbacks(context)
  File "/home/airflow/.local/lib/python3.6/site-packages/airflow/models/taskinstance.py", line 1460, in _execute_task_with_callbacks
    result = self._execute_task(context, self.task)
  File "/home/airflow/.local/lib/python3.6/site-packages/airflow/models/taskinstance.py", line 1516, in _execute_task
    result = execute_callable(context=context)
  File "/home/airflow/.local/lib/python3.6/site-packages/airflow/operators/python.py", line 174, in execute
    return_value = self.execute_callable()
  File "/home/airflow/.local/lib/python3.6/site-packages/airflow/operators/python.py", line 188, in execute_callable
    return self.python_callable(*self.op_args, **self.op_kwargs)
  File "/opt/airflow/scripts/scraper_consumer.py", line 42, in kafka_consumer_process
    conn = psycopg2.connect(**pg_conf)
  File "/home/airflow/.local/lib/python3.6/site-packages/psycopg2/__init__.py", line 122, in connect
    conn = _connect(dsn, connection_factory=connection_factory, **kwasync)
psycopg2.OperationalError: connection to server at "localhost" (127.0.0.1), port 5432 failed: Connection refused
	Is the server running on that host and accepting TCP/IP connections?
connection to server at "localhost" (::1), port 5432 failed: Cannot assign requested address
	Is the server running on that host and accepting TCP/IP connections?

[2024-06-26 16:35:05,121] {taskinstance.py:1282} INFO - Marking task as UP_FOR_RETRY. dag_id=kafka_consumer_dag, task_id=run_kafka_consumer, execution_date=20230101T052500, start_date=20240626T163504, end_date=20240626T163505
[2024-06-26 16:35:05,139] {standard_task_runner.py:92} ERROR - Failed to execute job 3127 for task run_kafka_consumer
Traceback (most recent call last):
  File "/home/airflow/.local/lib/python3.6/site-packages/airflow/task/task_runner/standard_task_runner.py", line 85, in _start_by_fork
    args.func(args, dag=self.dag)
  File "/home/airflow/.local/lib/python3.6/site-packages/airflow/cli/cli_parser.py", line 48, in command
    return func(*args, **kwargs)
  File "/home/airflow/.local/lib/python3.6/site-packages/airflow/utils/cli.py", line 92, in wrapper
    return f(*args, **kwargs)
  File "/home/airflow/.local/lib/python3.6/site-packages/airflow/cli/commands/task_command.py", line 298, in task_run
    _run_task_by_selected_method(args, dag, ti)
  File "/home/airflow/.local/lib/python3.6/site-packages/airflow/cli/commands/task_command.py", line 107, in _run_task_by_selected_method
    _run_raw_task(args, ti)
  File "/home/airflow/.local/lib/python3.6/site-packages/airflow/cli/commands/task_command.py", line 184, in _run_raw_task
    error_file=args.error_file,
  File "/home/airflow/.local/lib/python3.6/site-packages/airflow/utils/session.py", line 70, in wrapper
    return func(*args, session=session, **kwargs)
  File "/home/airflow/.local/lib/python3.6/site-packages/airflow/models/taskinstance.py", line 1334, in _run_raw_task
    self._execute_task_with_callbacks(context)
  File "/home/airflow/.local/lib/python3.6/site-packages/airflow/models/taskinstance.py", line 1460, in _execute_task_with_callbacks
    result = self._execute_task(context, self.task)
  File "/home/airflow/.local/lib/python3.6/site-packages/airflow/models/taskinstance.py", line 1516, in _execute_task
    result = execute_callable(context=context)
  File "/home/airflow/.local/lib/python3.6/site-packages/airflow/operators/python.py", line 174, in execute
    return_value = self.execute_callable()
  File "/home/airflow/.local/lib/python3.6/site-packages/airflow/operators/python.py", line 188, in execute_callable
    return self.python_callable(*self.op_args, **self.op_kwargs)
  File "/opt/airflow/scripts/scraper_consumer.py", line 42, in kafka_consumer_process
    conn = psycopg2.connect(**pg_conf)
  File "/home/airflow/.local/lib/python3.6/site-packages/psycopg2/__init__.py", line 122, in connect
    conn = _connect(dsn, connection_factory=connection_factory, **kwasync)
psycopg2.OperationalError: connection to server at "localhost" (127.0.0.1), port 5432 failed: Connection refused
	Is the server running on that host and accepting TCP/IP connections?
connection to server at "localhost" (::1), port 5432 failed: Cannot assign requested address
	Is the server running on that host and accepting TCP/IP connections?

[2024-06-26 16:35:05,147] {local_task_job.py:154} INFO - Task exited with return code 1
[2024-06-26 16:35:05,199] {local_task_job.py:264} INFO - 0 downstream tasks scheduled from follow-on schedule check
