[2024-06-25 03:48:25,584] {taskinstance.py:1037} INFO - Dependencies all met for <TaskInstance: text_processing_dag_1.process_text manual__2024-06-25T03:43:17.483007+00:00 [queued]>
[2024-06-25 03:48:25,596] {taskinstance.py:1037} INFO - Dependencies all met for <TaskInstance: text_processing_dag_1.process_text manual__2024-06-25T03:43:17.483007+00:00 [queued]>
[2024-06-25 03:48:25,597] {taskinstance.py:1243} INFO - 
--------------------------------------------------------------------------------
[2024-06-25 03:48:25,597] {taskinstance.py:1244} INFO - Starting attempt 2 of 2
[2024-06-25 03:48:25,597] {taskinstance.py:1245} INFO - 
--------------------------------------------------------------------------------
[2024-06-25 03:48:25,610] {taskinstance.py:1264} INFO - Executing <Task(PythonOperator): process_text> on 2024-06-25 03:43:17.483007+00:00
[2024-06-25 03:48:25,615] {standard_task_runner.py:52} INFO - Started process 563 to run task
[2024-06-25 03:48:25,619] {standard_task_runner.py:76} INFO - Running: ['airflow', 'tasks', 'run', 'text_processing_dag_1', 'process_text', 'manual__2024-06-25T03:43:17.483007+00:00', '--job-id', '113', '--raw', '--subdir', 'DAGS_FOLDER/dag_text_processing_1.py', '--cfg-path', '/tmp/tmpqx2mo4w1', '--error-file', '/tmp/tmpl3n3vcki']
[2024-06-25 03:48:25,623] {standard_task_runner.py:77} INFO - Job 113: Subtask process_text
[2024-06-25 03:48:25,700] {logging_mixin.py:109} INFO - Running <TaskInstance: text_processing_dag_1.process_text manual__2024-06-25T03:43:17.483007+00:00 [running]> on host 09709d0d4538
[2024-06-25 03:48:25,765] {taskinstance.py:1431} INFO - Exporting the following env vars:
AIRFLOW_CTX_DAG_OWNER=airflow
AIRFLOW_CTX_DAG_ID=text_processing_dag_1
AIRFLOW_CTX_TASK_ID=process_text
AIRFLOW_CTX_EXECUTION_DATE=2024-06-25T03:43:17.483007+00:00
AIRFLOW_CTX_DAG_RUN_ID=manual__2024-06-25T03:43:17.483007+00:00
[2024-06-25 03:48:26,473] {logging_mixin.py:109} INFO - Error decoding JSON: Expecting ',' delimiter: line 1 column 318 (char 317)
[2024-06-25 03:48:26,473] {logging_mixin.py:109} INFO - Error decoding JSON: Expecting ',' delimiter: line 1 column 321 (char 320)
[2024-06-25 03:48:26,473] {logging_mixin.py:109} INFO - Error decoding JSON: Expecting ',' delimiter: line 1 column 82 (char 81)
[2024-06-25 03:48:26,474] {logging_mixin.py:109} INFO - Error decoding JSON: Expecting ',' delimiter: line 1 column 83 (char 82)
[2024-06-25 03:48:26,506] {taskinstance.py:1718} ERROR - Task failed with exception
Traceback (most recent call last):
  File "/home/airflow/.local/lib/python3.6/site-packages/pandas/core/indexes/base.py", line 2898, in get_loc
    return self._engine.get_loc(casted_key)
  File "pandas/_libs/index.pyx", line 70, in pandas._libs.index.IndexEngine.get_loc
  File "pandas/_libs/index.pyx", line 101, in pandas._libs.index.IndexEngine.get_loc
  File "pandas/_libs/hashtable_class_helper.pxi", line 1675, in pandas._libs.hashtable.PyObjectHashTable.get_item
  File "pandas/_libs/hashtable_class_helper.pxi", line 1683, in pandas._libs.hashtable.PyObjectHashTable.get_item
KeyError: 'message'

The above exception was the direct cause of the following exception:

Traceback (most recent call last):
  File "/home/airflow/.local/lib/python3.6/site-packages/airflow/models/taskinstance.py", line 1334, in _run_raw_task
    self._execute_task_with_callbacks(context)
  File "/home/airflow/.local/lib/python3.6/site-packages/airflow/models/taskinstance.py", line 1460, in _execute_task_with_callbacks
    result = self._execute_task(context, self.task)
  File "/home/airflow/.local/lib/python3.6/site-packages/airflow/models/taskinstance.py", line 1516, in _execute_task
    result = execute_callable(context=context)
  File "/home/airflow/.local/lib/python3.6/site-packages/airflow/operators/python.py", line 174, in execute
    return_value = self.execute_callable()
  File "/home/airflow/.local/lib/python3.6/site-packages/airflow/operators/python.py", line 188, in execute_callable
    return self.python_callable(*self.op_args, **self.op_kwargs)
  File "/opt/airflow/dags/../scripts/text_processing.py", line 34, in process_text
    df = df[df['message'].str.contains('protest', case=False, na=False)]
  File "/home/airflow/.local/lib/python3.6/site-packages/pandas/core/frame.py", line 2906, in __getitem__
    indexer = self.columns.get_loc(key)
  File "/home/airflow/.local/lib/python3.6/site-packages/pandas/core/indexes/base.py", line 2900, in get_loc
    raise KeyError(key) from err
KeyError: 'message'
[2024-06-25 03:48:26,524] {taskinstance.py:1282} INFO - Marking task as FAILED. dag_id=text_processing_dag_1, task_id=process_text, execution_date=20240625T034317, start_date=20240625T034825, end_date=20240625T034826
[2024-06-25 03:48:26,541] {standard_task_runner.py:92} ERROR - Failed to execute job 113 for task process_text
Traceback (most recent call last):
  File "/home/airflow/.local/lib/python3.6/site-packages/pandas/core/indexes/base.py", line 2898, in get_loc
    return self._engine.get_loc(casted_key)
  File "pandas/_libs/index.pyx", line 70, in pandas._libs.index.IndexEngine.get_loc
  File "pandas/_libs/index.pyx", line 101, in pandas._libs.index.IndexEngine.get_loc
  File "pandas/_libs/hashtable_class_helper.pxi", line 1675, in pandas._libs.hashtable.PyObjectHashTable.get_item
  File "pandas/_libs/hashtable_class_helper.pxi", line 1683, in pandas._libs.hashtable.PyObjectHashTable.get_item
KeyError: 'message'

The above exception was the direct cause of the following exception:

Traceback (most recent call last):
  File "/home/airflow/.local/lib/python3.6/site-packages/airflow/task/task_runner/standard_task_runner.py", line 85, in _start_by_fork
    args.func(args, dag=self.dag)
  File "/home/airflow/.local/lib/python3.6/site-packages/airflow/cli/cli_parser.py", line 48, in command
    return func(*args, **kwargs)
  File "/home/airflow/.local/lib/python3.6/site-packages/airflow/utils/cli.py", line 92, in wrapper
    return f(*args, **kwargs)
  File "/home/airflow/.local/lib/python3.6/site-packages/airflow/cli/commands/task_command.py", line 298, in task_run
    _run_task_by_selected_method(args, dag, ti)
  File "/home/airflow/.local/lib/python3.6/site-packages/airflow/cli/commands/task_command.py", line 107, in _run_task_by_selected_method
    _run_raw_task(args, ti)
  File "/home/airflow/.local/lib/python3.6/site-packages/airflow/cli/commands/task_command.py", line 184, in _run_raw_task
    error_file=args.error_file,
  File "/home/airflow/.local/lib/python3.6/site-packages/airflow/utils/session.py", line 70, in wrapper
    return func(*args, session=session, **kwargs)
  File "/home/airflow/.local/lib/python3.6/site-packages/airflow/models/taskinstance.py", line 1334, in _run_raw_task
    self._execute_task_with_callbacks(context)
  File "/home/airflow/.local/lib/python3.6/site-packages/airflow/models/taskinstance.py", line 1460, in _execute_task_with_callbacks
    result = self._execute_task(context, self.task)
  File "/home/airflow/.local/lib/python3.6/site-packages/airflow/models/taskinstance.py", line 1516, in _execute_task
    result = execute_callable(context=context)
  File "/home/airflow/.local/lib/python3.6/site-packages/airflow/operators/python.py", line 174, in execute
    return_value = self.execute_callable()
  File "/home/airflow/.local/lib/python3.6/site-packages/airflow/operators/python.py", line 188, in execute_callable
    return self.python_callable(*self.op_args, **self.op_kwargs)
  File "/opt/airflow/dags/../scripts/text_processing.py", line 34, in process_text
    df = df[df['message'].str.contains('protest', case=False, na=False)]
  File "/home/airflow/.local/lib/python3.6/site-packages/pandas/core/frame.py", line 2906, in __getitem__
    indexer = self.columns.get_loc(key)
  File "/home/airflow/.local/lib/python3.6/site-packages/pandas/core/indexes/base.py", line 2900, in get_loc
    raise KeyError(key) from err
KeyError: 'message'
[2024-06-25 03:48:26,563] {local_task_job.py:154} INFO - Task exited with return code 1
[2024-06-25 03:48:26,609] {local_task_job.py:264} INFO - 0 downstream tasks scheduled from follow-on schedule check
