[2024-06-20 20:17:27,272] {taskinstance.py:1037} INFO - Dependencies all met for <TaskInstance: text_processing_dag_1.process_text manual__2024-06-20T20:12:16.366801+00:00 [queued]>
[2024-06-20 20:17:27,301] {taskinstance.py:1037} INFO - Dependencies all met for <TaskInstance: text_processing_dag_1.process_text manual__2024-06-20T20:12:16.366801+00:00 [queued]>
[2024-06-20 20:17:27,301] {taskinstance.py:1243} INFO - 
--------------------------------------------------------------------------------
[2024-06-20 20:17:27,302] {taskinstance.py:1244} INFO - Starting attempt 2 of 2
[2024-06-20 20:17:27,302] {taskinstance.py:1245} INFO - 
--------------------------------------------------------------------------------
[2024-06-20 20:17:27,332] {taskinstance.py:1264} INFO - Executing <Task(PythonOperator): process_text> on 2024-06-20 20:12:16.366801+00:00
[2024-06-20 20:17:27,342] {standard_task_runner.py:52} INFO - Started process 465 to run task
[2024-06-20 20:17:27,354] {standard_task_runner.py:76} INFO - Running: ['airflow', 'tasks', 'run', 'text_processing_dag_1', 'process_text', 'manual__2024-06-20T20:12:16.366801+00:00', '--job-id', '39', '--raw', '--subdir', 'DAGS_FOLDER/dag_text_processing_1.py', '--cfg-path', '/tmp/tmpch7pnpgm', '--error-file', '/tmp/tmpzmgbo_1i']
[2024-06-20 20:17:27,363] {standard_task_runner.py:77} INFO - Job 39: Subtask process_text
[2024-06-20 20:17:27,542] {logging_mixin.py:109} INFO - Running <TaskInstance: text_processing_dag_1.process_text manual__2024-06-20T20:12:16.366801+00:00 [running]> on host 659bb847486a
[2024-06-20 20:17:27,744] {taskinstance.py:1431} INFO - Exporting the following env vars:
AIRFLOW_CTX_DAG_OWNER=airflow
AIRFLOW_CTX_DAG_ID=text_processing_dag_1
AIRFLOW_CTX_TASK_ID=process_text
AIRFLOW_CTX_EXECUTION_DATE=2024-06-20T20:12:16.366801+00:00
AIRFLOW_CTX_DAG_RUN_ID=manual__2024-06-20T20:12:16.366801+00:00
[2024-06-20 20:17:30,604] {taskinstance.py:1718} ERROR - Task failed with exception
Traceback (most recent call last):
  File "/home/airflow/.local/lib/python3.6/site-packages/airflow/models/taskinstance.py", line 1334, in _run_raw_task
    self._execute_task_with_callbacks(context)
  File "/home/airflow/.local/lib/python3.6/site-packages/airflow/models/taskinstance.py", line 1460, in _execute_task_with_callbacks
    result = self._execute_task(context, self.task)
  File "/home/airflow/.local/lib/python3.6/site-packages/airflow/models/taskinstance.py", line 1516, in _execute_task
    result = execute_callable(context=context)
  File "/home/airflow/.local/lib/python3.6/site-packages/airflow/operators/python.py", line 174, in execute
    return_value = self.execute_callable()
  File "/home/airflow/.local/lib/python3.6/site-packages/airflow/operators/python.py", line 188, in execute_callable
    return self.python_callable(*self.op_args, **self.op_kwargs)
  File "/opt/airflow/dags/../scripts/text_processing.py", line 19, in process_text
    with open(input_path, 'r') as file:
FileNotFoundError: [Errno 2] No such file or directory: '/home/mhmdghdbn/airflow/zookeeper/airflow/data/output.json'
[2024-06-20 20:17:30,664] {taskinstance.py:1282} INFO - Marking task as FAILED. dag_id=text_processing_dag_1, task_id=process_text, execution_date=20240620T201216, start_date=20240620T201727, end_date=20240620T201730
[2024-06-20 20:17:30,703] {standard_task_runner.py:92} ERROR - Failed to execute job 39 for task process_text
Traceback (most recent call last):
  File "/home/airflow/.local/lib/python3.6/site-packages/airflow/task/task_runner/standard_task_runner.py", line 85, in _start_by_fork
    args.func(args, dag=self.dag)
  File "/home/airflow/.local/lib/python3.6/site-packages/airflow/cli/cli_parser.py", line 48, in command
    return func(*args, **kwargs)
  File "/home/airflow/.local/lib/python3.6/site-packages/airflow/utils/cli.py", line 92, in wrapper
    return f(*args, **kwargs)
  File "/home/airflow/.local/lib/python3.6/site-packages/airflow/cli/commands/task_command.py", line 298, in task_run
    _run_task_by_selected_method(args, dag, ti)
  File "/home/airflow/.local/lib/python3.6/site-packages/airflow/cli/commands/task_command.py", line 107, in _run_task_by_selected_method
    _run_raw_task(args, ti)
  File "/home/airflow/.local/lib/python3.6/site-packages/airflow/cli/commands/task_command.py", line 184, in _run_raw_task
    error_file=args.error_file,
  File "/home/airflow/.local/lib/python3.6/site-packages/airflow/utils/session.py", line 70, in wrapper
    return func(*args, session=session, **kwargs)
  File "/home/airflow/.local/lib/python3.6/site-packages/airflow/models/taskinstance.py", line 1334, in _run_raw_task
    self._execute_task_with_callbacks(context)
  File "/home/airflow/.local/lib/python3.6/site-packages/airflow/models/taskinstance.py", line 1460, in _execute_task_with_callbacks
    result = self._execute_task(context, self.task)
  File "/home/airflow/.local/lib/python3.6/site-packages/airflow/models/taskinstance.py", line 1516, in _execute_task
    result = execute_callable(context=context)
  File "/home/airflow/.local/lib/python3.6/site-packages/airflow/operators/python.py", line 174, in execute
    return_value = self.execute_callable()
  File "/home/airflow/.local/lib/python3.6/site-packages/airflow/operators/python.py", line 188, in execute_callable
    return self.python_callable(*self.op_args, **self.op_kwargs)
  File "/opt/airflow/dags/../scripts/text_processing.py", line 19, in process_text
    with open(input_path, 'r') as file:
FileNotFoundError: [Errno 2] No such file or directory: '/home/mhmdghdbn/airflow/zookeeper/airflow/data/output.json'
[2024-06-20 20:17:30,762] {local_task_job.py:154} INFO - Task exited with return code 1
[2024-06-20 20:17:31,026] {local_task_job.py:264} INFO - 0 downstream tasks scheduled from follow-on schedule check
