[2024-06-20 19:32:20,033] {taskinstance.py:1037} INFO - Dependencies all met for <TaskInstance: text_processing_dag_2.process_text scheduled__2024-06-18T00:00:00+00:00 [queued]>
[2024-06-20 19:32:20,167] {taskinstance.py:1037} INFO - Dependencies all met for <TaskInstance: text_processing_dag_2.process_text scheduled__2024-06-18T00:00:00+00:00 [queued]>
[2024-06-20 19:32:20,177] {taskinstance.py:1243} INFO - 
--------------------------------------------------------------------------------
[2024-06-20 19:32:20,187] {taskinstance.py:1244} INFO - Starting attempt 1 of 2
[2024-06-20 19:32:20,189] {taskinstance.py:1245} INFO - 
--------------------------------------------------------------------------------
[2024-06-20 19:32:20,297] {taskinstance.py:1264} INFO - Executing <Task(PythonOperator): process_text> on 2024-06-18 00:00:00+00:00
[2024-06-20 19:32:20,326] {standard_task_runner.py:52} INFO - Started process 243 to run task
[2024-06-20 19:32:20,375] {standard_task_runner.py:76} INFO - Running: ['airflow', 'tasks', 'run', 'text_processing_dag_2', 'process_text', 'scheduled__2024-06-18T00:00:00+00:00', '--job-id', '9', '--raw', '--subdir', 'DAGS_FOLDER/dag_text_processing_2.py', '--cfg-path', '/tmp/tmptx8dj1z4', '--error-file', '/tmp/tmp4f_8n3gp']
[2024-06-20 19:32:20,426] {standard_task_runner.py:77} INFO - Job 9: Subtask process_text
[2024-06-20 19:32:20,929] {logging_mixin.py:109} INFO - Running <TaskInstance: text_processing_dag_2.process_text scheduled__2024-06-18T00:00:00+00:00 [running]> on host 09fa9687a8d2
[2024-06-20 19:32:21,286] {taskinstance.py:1431} INFO - Exporting the following env vars:
AIRFLOW_CTX_DAG_OWNER=airflow
AIRFLOW_CTX_DAG_ID=text_processing_dag_2
AIRFLOW_CTX_TASK_ID=process_text
AIRFLOW_CTX_EXECUTION_DATE=2024-06-18T00:00:00+00:00
AIRFLOW_CTX_DAG_RUN_ID=scheduled__2024-06-18T00:00:00+00:00
[2024-06-20 19:32:26,338] {taskinstance.py:1718} ERROR - Task failed with exception
Traceback (most recent call last):
  File "/home/airflow/.local/lib/python3.6/site-packages/airflow/models/taskinstance.py", line 1334, in _run_raw_task
    self._execute_task_with_callbacks(context)
  File "/home/airflow/.local/lib/python3.6/site-packages/airflow/models/taskinstance.py", line 1460, in _execute_task_with_callbacks
    result = self._execute_task(context, self.task)
  File "/home/airflow/.local/lib/python3.6/site-packages/airflow/models/taskinstance.py", line 1516, in _execute_task
    result = execute_callable(context=context)
  File "/home/airflow/.local/lib/python3.6/site-packages/airflow/operators/python.py", line 174, in execute
    return_value = self.execute_callable()
  File "/home/airflow/.local/lib/python3.6/site-packages/airflow/operators/python.py", line 188, in execute_callable
    return self.python_callable(*self.op_args, **self.op_kwargs)
  File "/opt/airflow/dags/../scripts/text_processing.py", line 16, in process_text
    nlp = spacy.load("en_core_web_sm")
  File "/home/airflow/.local/lib/python3.6/site-packages/spacy/__init__.py", line 57, in load
    config=config,
  File "/home/airflow/.local/lib/python3.6/site-packages/spacy/util.py", line 472, in load_model
    raise IOError(Errors.E050.format(name=name))
OSError: [E050] Can't find model 'en_core_web_sm'. It doesn't seem to be a Python package or a valid path to a data directory.
[2024-06-20 19:32:26,472] {taskinstance.py:1282} INFO - Marking task as UP_FOR_RETRY. dag_id=text_processing_dag_2, task_id=process_text, execution_date=20240618T000000, start_date=20240620T193220, end_date=20240620T193226
[2024-06-20 19:32:26,966] {standard_task_runner.py:92} ERROR - Failed to execute job 9 for task process_text
Traceback (most recent call last):
  File "/home/airflow/.local/lib/python3.6/site-packages/airflow/task/task_runner/standard_task_runner.py", line 85, in _start_by_fork
    args.func(args, dag=self.dag)
  File "/home/airflow/.local/lib/python3.6/site-packages/airflow/cli/cli_parser.py", line 48, in command
    return func(*args, **kwargs)
  File "/home/airflow/.local/lib/python3.6/site-packages/airflow/utils/cli.py", line 92, in wrapper
    return f(*args, **kwargs)
  File "/home/airflow/.local/lib/python3.6/site-packages/airflow/cli/commands/task_command.py", line 298, in task_run
    _run_task_by_selected_method(args, dag, ti)
  File "/home/airflow/.local/lib/python3.6/site-packages/airflow/cli/commands/task_command.py", line 107, in _run_task_by_selected_method
    _run_raw_task(args, ti)
  File "/home/airflow/.local/lib/python3.6/site-packages/airflow/cli/commands/task_command.py", line 184, in _run_raw_task
    error_file=args.error_file,
  File "/home/airflow/.local/lib/python3.6/site-packages/airflow/utils/session.py", line 70, in wrapper
    return func(*args, session=session, **kwargs)
  File "/home/airflow/.local/lib/python3.6/site-packages/airflow/models/taskinstance.py", line 1334, in _run_raw_task
    self._execute_task_with_callbacks(context)
  File "/home/airflow/.local/lib/python3.6/site-packages/airflow/models/taskinstance.py", line 1460, in _execute_task_with_callbacks
    result = self._execute_task(context, self.task)
  File "/home/airflow/.local/lib/python3.6/site-packages/airflow/models/taskinstance.py", line 1516, in _execute_task
    result = execute_callable(context=context)
  File "/home/airflow/.local/lib/python3.6/site-packages/airflow/operators/python.py", line 174, in execute
    return_value = self.execute_callable()
  File "/home/airflow/.local/lib/python3.6/site-packages/airflow/operators/python.py", line 188, in execute_callable
    return self.python_callable(*self.op_args, **self.op_kwargs)
  File "/opt/airflow/dags/../scripts/text_processing.py", line 16, in process_text
    nlp = spacy.load("en_core_web_sm")
  File "/home/airflow/.local/lib/python3.6/site-packages/spacy/__init__.py", line 57, in load
    config=config,
  File "/home/airflow/.local/lib/python3.6/site-packages/spacy/util.py", line 472, in load_model
    raise IOError(Errors.E050.format(name=name))
OSError: [E050] Can't find model 'en_core_web_sm'. It doesn't seem to be a Python package or a valid path to a data directory.
[2024-06-20 19:32:27,001] {local_task_job.py:154} INFO - Task exited with return code 1
[2024-06-20 19:32:27,298] {local_task_job.py:264} INFO - 0 downstream tasks scheduled from follow-on schedule check
[2024-06-20 20:02:19,982] {taskinstance.py:1037} INFO - Dependencies all met for <TaskInstance: text_processing_dag_2.process_text scheduled__2024-06-18T00:00:00+00:00 [queued]>
[2024-06-20 20:02:19,996] {taskinstance.py:1037} INFO - Dependencies all met for <TaskInstance: text_processing_dag_2.process_text scheduled__2024-06-18T00:00:00+00:00 [queued]>
[2024-06-20 20:02:19,996] {taskinstance.py:1243} INFO - 
--------------------------------------------------------------------------------
[2024-06-20 20:02:19,996] {taskinstance.py:1244} INFO - Starting attempt 1 of 2
[2024-06-20 20:02:19,996] {taskinstance.py:1245} INFO - 
--------------------------------------------------------------------------------
[2024-06-20 20:02:20,009] {taskinstance.py:1264} INFO - Executing <Task(PythonOperator): process_text> on 2024-06-18 00:00:00+00:00
[2024-06-20 20:02:20,016] {standard_task_runner.py:52} INFO - Started process 354 to run task
[2024-06-20 20:02:20,025] {standard_task_runner.py:76} INFO - Running: ['airflow', 'tasks', 'run', 'text_processing_dag_2', 'process_text', 'scheduled__2024-06-18T00:00:00+00:00', '--job-id', '31', '--raw', '--subdir', 'DAGS_FOLDER/dag_text_processing_2.py', '--cfg-path', '/tmp/tmph4b5g0mv', '--error-file', '/tmp/tmpuu4b958r']
[2024-06-20 20:02:20,028] {standard_task_runner.py:77} INFO - Job 31: Subtask process_text
[2024-06-20 20:02:20,176] {logging_mixin.py:109} INFO - Running <TaskInstance: text_processing_dag_2.process_text scheduled__2024-06-18T00:00:00+00:00 [running]> on host b95ccdd7ac61
[2024-06-20 20:02:20,352] {taskinstance.py:1431} INFO - Exporting the following env vars:
AIRFLOW_CTX_DAG_OWNER=airflow
AIRFLOW_CTX_DAG_ID=text_processing_dag_2
AIRFLOW_CTX_TASK_ID=process_text
AIRFLOW_CTX_EXECUTION_DATE=2024-06-18T00:00:00+00:00
AIRFLOW_CTX_DAG_RUN_ID=scheduled__2024-06-18T00:00:00+00:00
[2024-06-20 20:02:20,590] {taskinstance.py:1718} ERROR - Task failed with exception
Traceback (most recent call last):
  File "/home/airflow/.local/lib/python3.6/site-packages/airflow/models/taskinstance.py", line 1334, in _run_raw_task
    self._execute_task_with_callbacks(context)
  File "/home/airflow/.local/lib/python3.6/site-packages/airflow/models/taskinstance.py", line 1460, in _execute_task_with_callbacks
    result = self._execute_task(context, self.task)
  File "/home/airflow/.local/lib/python3.6/site-packages/airflow/models/taskinstance.py", line 1516, in _execute_task
    result = execute_callable(context=context)
  File "/home/airflow/.local/lib/python3.6/site-packages/airflow/operators/python.py", line 174, in execute
    return_value = self.execute_callable()
  File "/home/airflow/.local/lib/python3.6/site-packages/airflow/operators/python.py", line 188, in execute_callable
    return self.python_callable(*self.op_args, **self.op_kwargs)
  File "/opt/airflow/dags/../scripts/text_processing.py", line 16, in process_text
    nlp = spacy.load("en_core_web_sm")
  File "/home/airflow/.local/lib/python3.6/site-packages/spacy/__init__.py", line 57, in load
    config=config,
  File "/home/airflow/.local/lib/python3.6/site-packages/spacy/util.py", line 472, in load_model
    raise IOError(Errors.E050.format(name=name))
OSError: [E050] Can't find model 'en_core_web_sm'. It doesn't seem to be a Python package or a valid path to a data directory.
[2024-06-20 20:02:20,609] {taskinstance.py:1282} INFO - Marking task as UP_FOR_RETRY. dag_id=text_processing_dag_2, task_id=process_text, execution_date=20240618T000000, start_date=20240620T200219, end_date=20240620T200220
[2024-06-20 20:02:20,628] {standard_task_runner.py:92} ERROR - Failed to execute job 31 for task process_text
Traceback (most recent call last):
  File "/home/airflow/.local/lib/python3.6/site-packages/airflow/task/task_runner/standard_task_runner.py", line 85, in _start_by_fork
    args.func(args, dag=self.dag)
  File "/home/airflow/.local/lib/python3.6/site-packages/airflow/cli/cli_parser.py", line 48, in command
    return func(*args, **kwargs)
  File "/home/airflow/.local/lib/python3.6/site-packages/airflow/utils/cli.py", line 92, in wrapper
    return f(*args, **kwargs)
  File "/home/airflow/.local/lib/python3.6/site-packages/airflow/cli/commands/task_command.py", line 298, in task_run
    _run_task_by_selected_method(args, dag, ti)
  File "/home/airflow/.local/lib/python3.6/site-packages/airflow/cli/commands/task_command.py", line 107, in _run_task_by_selected_method
    _run_raw_task(args, ti)
  File "/home/airflow/.local/lib/python3.6/site-packages/airflow/cli/commands/task_command.py", line 184, in _run_raw_task
    error_file=args.error_file,
  File "/home/airflow/.local/lib/python3.6/site-packages/airflow/utils/session.py", line 70, in wrapper
    return func(*args, session=session, **kwargs)
  File "/home/airflow/.local/lib/python3.6/site-packages/airflow/models/taskinstance.py", line 1334, in _run_raw_task
    self._execute_task_with_callbacks(context)
  File "/home/airflow/.local/lib/python3.6/site-packages/airflow/models/taskinstance.py", line 1460, in _execute_task_with_callbacks
    result = self._execute_task(context, self.task)
  File "/home/airflow/.local/lib/python3.6/site-packages/airflow/models/taskinstance.py", line 1516, in _execute_task
    result = execute_callable(context=context)
  File "/home/airflow/.local/lib/python3.6/site-packages/airflow/operators/python.py", line 174, in execute
    return_value = self.execute_callable()
  File "/home/airflow/.local/lib/python3.6/site-packages/airflow/operators/python.py", line 188, in execute_callable
    return self.python_callable(*self.op_args, **self.op_kwargs)
  File "/opt/airflow/dags/../scripts/text_processing.py", line 16, in process_text
    nlp = spacy.load("en_core_web_sm")
  File "/home/airflow/.local/lib/python3.6/site-packages/spacy/__init__.py", line 57, in load
    config=config,
  File "/home/airflow/.local/lib/python3.6/site-packages/spacy/util.py", line 472, in load_model
    raise IOError(Errors.E050.format(name=name))
OSError: [E050] Can't find model 'en_core_web_sm'. It doesn't seem to be a Python package or a valid path to a data directory.
[2024-06-20 20:02:20,643] {local_task_job.py:154} INFO - Task exited with return code 1
[2024-06-20 20:02:20,700] {local_task_job.py:264} INFO - 0 downstream tasks scheduled from follow-on schedule check
[2024-06-21 06:33:01,925] {taskinstance.py:1037} INFO - Dependencies all met for <TaskInstance: text_processing_dag_2.process_text scheduled__2024-06-18T00:00:00+00:00 [queued]>
[2024-06-21 06:33:01,972] {taskinstance.py:1037} INFO - Dependencies all met for <TaskInstance: text_processing_dag_2.process_text scheduled__2024-06-18T00:00:00+00:00 [queued]>
[2024-06-21 06:33:01,972] {taskinstance.py:1243} INFO - 
--------------------------------------------------------------------------------
[2024-06-21 06:33:01,972] {taskinstance.py:1244} INFO - Starting attempt 1 of 2
[2024-06-21 06:33:01,972] {taskinstance.py:1245} INFO - 
--------------------------------------------------------------------------------
[2024-06-21 06:33:02,037] {taskinstance.py:1264} INFO - Executing <Task(PythonOperator): process_text> on 2024-06-18 00:00:00+00:00
[2024-06-21 06:33:02,060] {standard_task_runner.py:52} INFO - Started process 260 to run task
[2024-06-21 06:33:02,086] {standard_task_runner.py:76} INFO - Running: ['airflow', 'tasks', 'run', 'text_processing_dag_2', 'process_text', 'scheduled__2024-06-18T00:00:00+00:00', '--job-id', '85', '--raw', '--subdir', 'DAGS_FOLDER/dag_text_processing_2.py', '--cfg-path', '/tmp/tmp40xfw38h', '--error-file', '/tmp/tmp4p2us8rs']
[2024-06-21 06:33:02,113] {standard_task_runner.py:77} INFO - Job 85: Subtask process_text
[2024-06-21 06:33:02,275] {logging_mixin.py:109} INFO - Running <TaskInstance: text_processing_dag_2.process_text scheduled__2024-06-18T00:00:00+00:00 [running]> on host 95c89469de59
[2024-06-21 06:33:02,491] {taskinstance.py:1431} INFO - Exporting the following env vars:
AIRFLOW_CTX_DAG_OWNER=airflow
AIRFLOW_CTX_DAG_ID=text_processing_dag_2
AIRFLOW_CTX_TASK_ID=process_text
AIRFLOW_CTX_EXECUTION_DATE=2024-06-18T00:00:00+00:00
AIRFLOW_CTX_DAG_RUN_ID=scheduled__2024-06-18T00:00:00+00:00
[2024-06-21 06:33:04,600] {taskinstance.py:1718} ERROR - Task failed with exception
Traceback (most recent call last):
  File "/home/airflow/.local/lib/python3.6/site-packages/airflow/models/taskinstance.py", line 1334, in _run_raw_task
    self._execute_task_with_callbacks(context)
  File "/home/airflow/.local/lib/python3.6/site-packages/airflow/models/taskinstance.py", line 1460, in _execute_task_with_callbacks
    result = self._execute_task(context, self.task)
  File "/home/airflow/.local/lib/python3.6/site-packages/airflow/models/taskinstance.py", line 1516, in _execute_task
    result = execute_callable(context=context)
  File "/home/airflow/.local/lib/python3.6/site-packages/airflow/operators/python.py", line 174, in execute
    return_value = self.execute_callable()
  File "/home/airflow/.local/lib/python3.6/site-packages/airflow/operators/python.py", line 188, in execute_callable
    return self.python_callable(*self.op_args, **self.op_kwargs)
  File "/opt/airflow/dags/../scripts/text_processing.py", line 20, in process_text
    with open(input_path, 'r') as file:
FileNotFoundError: [Errno 2] No such file or directory: '/opt/airflow/data/processed_data_1.json'
[2024-06-21 06:33:04,656] {taskinstance.py:1282} INFO - Marking task as UP_FOR_RETRY. dag_id=text_processing_dag_2, task_id=process_text, execution_date=20240618T000000, start_date=20240621T063301, end_date=20240621T063304
[2024-06-21 06:33:04,714] {standard_task_runner.py:92} ERROR - Failed to execute job 85 for task process_text
Traceback (most recent call last):
  File "/home/airflow/.local/lib/python3.6/site-packages/airflow/task/task_runner/standard_task_runner.py", line 85, in _start_by_fork
    args.func(args, dag=self.dag)
  File "/home/airflow/.local/lib/python3.6/site-packages/airflow/cli/cli_parser.py", line 48, in command
    return func(*args, **kwargs)
  File "/home/airflow/.local/lib/python3.6/site-packages/airflow/utils/cli.py", line 92, in wrapper
    return f(*args, **kwargs)
  File "/home/airflow/.local/lib/python3.6/site-packages/airflow/cli/commands/task_command.py", line 298, in task_run
    _run_task_by_selected_method(args, dag, ti)
  File "/home/airflow/.local/lib/python3.6/site-packages/airflow/cli/commands/task_command.py", line 107, in _run_task_by_selected_method
    _run_raw_task(args, ti)
  File "/home/airflow/.local/lib/python3.6/site-packages/airflow/cli/commands/task_command.py", line 184, in _run_raw_task
    error_file=args.error_file,
  File "/home/airflow/.local/lib/python3.6/site-packages/airflow/utils/session.py", line 70, in wrapper
    return func(*args, session=session, **kwargs)
  File "/home/airflow/.local/lib/python3.6/site-packages/airflow/models/taskinstance.py", line 1334, in _run_raw_task
    self._execute_task_with_callbacks(context)
  File "/home/airflow/.local/lib/python3.6/site-packages/airflow/models/taskinstance.py", line 1460, in _execute_task_with_callbacks
    result = self._execute_task(context, self.task)
  File "/home/airflow/.local/lib/python3.6/site-packages/airflow/models/taskinstance.py", line 1516, in _execute_task
    result = execute_callable(context=context)
  File "/home/airflow/.local/lib/python3.6/site-packages/airflow/operators/python.py", line 174, in execute
    return_value = self.execute_callable()
  File "/home/airflow/.local/lib/python3.6/site-packages/airflow/operators/python.py", line 188, in execute_callable
    return self.python_callable(*self.op_args, **self.op_kwargs)
  File "/opt/airflow/dags/../scripts/text_processing.py", line 20, in process_text
    with open(input_path, 'r') as file:
FileNotFoundError: [Errno 2] No such file or directory: '/opt/airflow/data/processed_data_1.json'
[2024-06-21 06:33:04,744] {local_task_job.py:154} INFO - Task exited with return code 1
[2024-06-21 06:33:04,827] {local_task_job.py:264} INFO - 0 downstream tasks scheduled from follow-on schedule check
[2024-06-25 04:55:09,631] {taskinstance.py:1037} INFO - Dependencies all met for <TaskInstance: text_processing_dag_2.process_text scheduled__2024-06-18T00:00:00+00:00 [queued]>
[2024-06-25 04:55:09,651] {taskinstance.py:1037} INFO - Dependencies all met for <TaskInstance: text_processing_dag_2.process_text scheduled__2024-06-18T00:00:00+00:00 [queued]>
[2024-06-25 04:55:09,651] {taskinstance.py:1243} INFO - 
--------------------------------------------------------------------------------
[2024-06-25 04:55:09,651] {taskinstance.py:1244} INFO - Starting attempt 1 of 2
[2024-06-25 04:55:09,651] {taskinstance.py:1245} INFO - 
--------------------------------------------------------------------------------
[2024-06-25 04:55:09,667] {taskinstance.py:1264} INFO - Executing <Task(PythonOperator): process_text> on 2024-06-18 00:00:00+00:00
[2024-06-25 04:55:09,675] {standard_task_runner.py:52} INFO - Started process 3422 to run task
[2024-06-25 04:55:09,685] {standard_task_runner.py:76} INFO - Running: ['airflow', 'tasks', 'run', 'text_processing_dag_2', 'process_text', 'scheduled__2024-06-18T00:00:00+00:00', '--job-id', '158', '--raw', '--subdir', 'DAGS_FOLDER/dag_text_processing_2.py', '--cfg-path', '/tmp/tmpunc6oxy8', '--error-file', '/tmp/tmpxew9tvz4']
[2024-06-25 04:55:09,688] {standard_task_runner.py:77} INFO - Job 158: Subtask process_text
[2024-06-25 04:55:09,774] {logging_mixin.py:109} INFO - Running <TaskInstance: text_processing_dag_2.process_text scheduled__2024-06-18T00:00:00+00:00 [running]> on host 09709d0d4538
[2024-06-25 04:55:09,857] {taskinstance.py:1431} INFO - Exporting the following env vars:
AIRFLOW_CTX_DAG_OWNER=airflow
AIRFLOW_CTX_DAG_ID=text_processing_dag_2
AIRFLOW_CTX_TASK_ID=process_text
AIRFLOW_CTX_EXECUTION_DATE=2024-06-18T00:00:00+00:00
AIRFLOW_CTX_DAG_RUN_ID=scheduled__2024-06-18T00:00:00+00:00
[2024-06-25 04:55:10,914] {taskinstance.py:1718} ERROR - Task failed with exception
Traceback (most recent call last):
  File "/home/airflow/.local/lib/python3.6/site-packages/airflow/models/taskinstance.py", line 1334, in _run_raw_task
    self._execute_task_with_callbacks(context)
  File "/home/airflow/.local/lib/python3.6/site-packages/airflow/models/taskinstance.py", line 1460, in _execute_task_with_callbacks
    result = self._execute_task(context, self.task)
  File "/home/airflow/.local/lib/python3.6/site-packages/airflow/models/taskinstance.py", line 1516, in _execute_task
    result = execute_callable(context=context)
  File "/home/airflow/.local/lib/python3.6/site-packages/airflow/operators/python.py", line 174, in execute
    return_value = self.execute_callable()
  File "/home/airflow/.local/lib/python3.6/site-packages/airflow/operators/python.py", line 188, in execute_callable
    return self.python_callable(*self.op_args, **self.op_kwargs)
  File "/opt/airflow/dags/../scripts/text_processing.py", line 19, in process_text
    df = pd.read_csv(input_path)
  File "/home/airflow/.local/lib/python3.6/site-packages/pandas/io/parsers.py", line 688, in read_csv
    return _read(filepath_or_buffer, kwds)
  File "/home/airflow/.local/lib/python3.6/site-packages/pandas/io/parsers.py", line 454, in _read
    parser = TextFileReader(fp_or_buf, **kwds)
  File "/home/airflow/.local/lib/python3.6/site-packages/pandas/io/parsers.py", line 948, in __init__
    self._make_engine(self.engine)
  File "/home/airflow/.local/lib/python3.6/site-packages/pandas/io/parsers.py", line 1180, in _make_engine
    self._engine = CParserWrapper(self.f, **self.options)
  File "/home/airflow/.local/lib/python3.6/site-packages/pandas/io/parsers.py", line 2010, in __init__
    self._reader = parsers.TextReader(src, **kwds)
  File "pandas/_libs/parsers.pyx", line 382, in pandas._libs.parsers.TextReader.__cinit__
  File "pandas/_libs/parsers.pyx", line 674, in pandas._libs.parsers.TextReader._setup_parser_source
FileNotFoundError: [Errno 2] No such file or directory: '/opt/airflow/data/processed_data_1.json'
[2024-06-25 04:55:10,936] {taskinstance.py:1282} INFO - Marking task as UP_FOR_RETRY. dag_id=text_processing_dag_2, task_id=process_text, execution_date=20240618T000000, start_date=20240625T045509, end_date=20240625T045510
[2024-06-25 04:55:11,116] {standard_task_runner.py:92} ERROR - Failed to execute job 158 for task process_text
Traceback (most recent call last):
  File "/home/airflow/.local/lib/python3.6/site-packages/airflow/task/task_runner/standard_task_runner.py", line 85, in _start_by_fork
    args.func(args, dag=self.dag)
  File "/home/airflow/.local/lib/python3.6/site-packages/airflow/cli/cli_parser.py", line 48, in command
    return func(*args, **kwargs)
  File "/home/airflow/.local/lib/python3.6/site-packages/airflow/utils/cli.py", line 92, in wrapper
    return f(*args, **kwargs)
  File "/home/airflow/.local/lib/python3.6/site-packages/airflow/cli/commands/task_command.py", line 298, in task_run
    _run_task_by_selected_method(args, dag, ti)
  File "/home/airflow/.local/lib/python3.6/site-packages/airflow/cli/commands/task_command.py", line 107, in _run_task_by_selected_method
    _run_raw_task(args, ti)
  File "/home/airflow/.local/lib/python3.6/site-packages/airflow/cli/commands/task_command.py", line 184, in _run_raw_task
    error_file=args.error_file,
  File "/home/airflow/.local/lib/python3.6/site-packages/airflow/utils/session.py", line 70, in wrapper
    return func(*args, session=session, **kwargs)
  File "/home/airflow/.local/lib/python3.6/site-packages/airflow/models/taskinstance.py", line 1334, in _run_raw_task
    self._execute_task_with_callbacks(context)
  File "/home/airflow/.local/lib/python3.6/site-packages/airflow/models/taskinstance.py", line 1460, in _execute_task_with_callbacks
    result = self._execute_task(context, self.task)
  File "/home/airflow/.local/lib/python3.6/site-packages/airflow/models/taskinstance.py", line 1516, in _execute_task
    result = execute_callable(context=context)
  File "/home/airflow/.local/lib/python3.6/site-packages/airflow/operators/python.py", line 174, in execute
    return_value = self.execute_callable()
  File "/home/airflow/.local/lib/python3.6/site-packages/airflow/operators/python.py", line 188, in execute_callable
    return self.python_callable(*self.op_args, **self.op_kwargs)
  File "/opt/airflow/dags/../scripts/text_processing.py", line 19, in process_text
    df = pd.read_csv(input_path)
  File "/home/airflow/.local/lib/python3.6/site-packages/pandas/io/parsers.py", line 688, in read_csv
    return _read(filepath_or_buffer, kwds)
  File "/home/airflow/.local/lib/python3.6/site-packages/pandas/io/parsers.py", line 454, in _read
    parser = TextFileReader(fp_or_buf, **kwds)
  File "/home/airflow/.local/lib/python3.6/site-packages/pandas/io/parsers.py", line 948, in __init__
    self._make_engine(self.engine)
  File "/home/airflow/.local/lib/python3.6/site-packages/pandas/io/parsers.py", line 1180, in _make_engine
    self._engine = CParserWrapper(self.f, **self.options)
  File "/home/airflow/.local/lib/python3.6/site-packages/pandas/io/parsers.py", line 2010, in __init__
    self._reader = parsers.TextReader(src, **kwds)
  File "pandas/_libs/parsers.pyx", line 382, in pandas._libs.parsers.TextReader.__cinit__
  File "pandas/_libs/parsers.pyx", line 674, in pandas._libs.parsers.TextReader._setup_parser_source
FileNotFoundError: [Errno 2] No such file or directory: '/opt/airflow/data/processed_data_1.json'
[2024-06-25 04:55:11,154] {local_task_job.py:154} INFO - Task exited with return code 1
[2024-06-25 04:55:11,212] {local_task_job.py:264} INFO - 0 downstream tasks scheduled from follow-on schedule check
[2024-06-25 04:55:41,876] {taskinstance.py:1037} INFO - Dependencies all met for <TaskInstance: text_processing_dag_2.process_text scheduled__2024-06-18T00:00:00+00:00 [queued]>
[2024-06-25 04:55:41,910] {taskinstance.py:1037} INFO - Dependencies all met for <TaskInstance: text_processing_dag_2.process_text scheduled__2024-06-18T00:00:00+00:00 [queued]>
[2024-06-25 04:55:41,910] {taskinstance.py:1243} INFO - 
--------------------------------------------------------------------------------
[2024-06-25 04:55:41,910] {taskinstance.py:1244} INFO - Starting attempt 1 of 2
[2024-06-25 04:55:41,910] {taskinstance.py:1245} INFO - 
--------------------------------------------------------------------------------
[2024-06-25 04:55:41,944] {taskinstance.py:1264} INFO - Executing <Task(PythonOperator): process_text> on 2024-06-18 00:00:00+00:00
[2024-06-25 04:55:41,961] {standard_task_runner.py:76} INFO - Running: ['airflow', 'tasks', 'run', 'text_processing_dag_2', 'process_text', 'scheduled__2024-06-18T00:00:00+00:00', '--job-id', '171', '--raw', '--subdir', 'DAGS_FOLDER/dag_text_processing_2.py', '--cfg-path', '/tmp/tmpd6m4mmn_', '--error-file', '/tmp/tmpvrhxwflq']
[2024-06-25 04:55:41,965] {standard_task_runner.py:77} INFO - Job 171: Subtask process_text
[2024-06-25 04:55:41,955] {standard_task_runner.py:52} INFO - Started process 3490 to run task
[2024-06-25 04:55:42,049] {logging_mixin.py:109} INFO - Running <TaskInstance: text_processing_dag_2.process_text scheduled__2024-06-18T00:00:00+00:00 [running]> on host 09709d0d4538
[2024-06-25 04:55:42,151] {taskinstance.py:1431} INFO - Exporting the following env vars:
AIRFLOW_CTX_DAG_OWNER=airflow
AIRFLOW_CTX_DAG_ID=text_processing_dag_2
AIRFLOW_CTX_TASK_ID=process_text
AIRFLOW_CTX_EXECUTION_DATE=2024-06-18T00:00:00+00:00
AIRFLOW_CTX_DAG_RUN_ID=scheduled__2024-06-18T00:00:00+00:00
[2024-06-25 04:55:42,998] {taskinstance.py:1718} ERROR - Task failed with exception
Traceback (most recent call last):
  File "/home/airflow/.local/lib/python3.6/site-packages/airflow/models/taskinstance.py", line 1334, in _run_raw_task
    self._execute_task_with_callbacks(context)
  File "/home/airflow/.local/lib/python3.6/site-packages/airflow/models/taskinstance.py", line 1460, in _execute_task_with_callbacks
    result = self._execute_task(context, self.task)
  File "/home/airflow/.local/lib/python3.6/site-packages/airflow/models/taskinstance.py", line 1516, in _execute_task
    result = execute_callable(context=context)
  File "/home/airflow/.local/lib/python3.6/site-packages/airflow/operators/python.py", line 174, in execute
    return_value = self.execute_callable()
  File "/home/airflow/.local/lib/python3.6/site-packages/airflow/operators/python.py", line 188, in execute_callable
    return self.python_callable(*self.op_args, **self.op_kwargs)
  File "/opt/airflow/dags/../scripts/text_processing.py", line 19, in process_text
    df = pd.read_csv(input_path)
  File "/home/airflow/.local/lib/python3.6/site-packages/pandas/io/parsers.py", line 688, in read_csv
    return _read(filepath_or_buffer, kwds)
  File "/home/airflow/.local/lib/python3.6/site-packages/pandas/io/parsers.py", line 454, in _read
    parser = TextFileReader(fp_or_buf, **kwds)
  File "/home/airflow/.local/lib/python3.6/site-packages/pandas/io/parsers.py", line 948, in __init__
    self._make_engine(self.engine)
  File "/home/airflow/.local/lib/python3.6/site-packages/pandas/io/parsers.py", line 1180, in _make_engine
    self._engine = CParserWrapper(self.f, **self.options)
  File "/home/airflow/.local/lib/python3.6/site-packages/pandas/io/parsers.py", line 2010, in __init__
    self._reader = parsers.TextReader(src, **kwds)
  File "pandas/_libs/parsers.pyx", line 382, in pandas._libs.parsers.TextReader.__cinit__
  File "pandas/_libs/parsers.pyx", line 674, in pandas._libs.parsers.TextReader._setup_parser_source
FileNotFoundError: [Errno 2] No such file or directory: '/opt/airflow/data/processed_data_1.json'
[2024-06-25 04:55:43,026] {taskinstance.py:1282} INFO - Marking task as UP_FOR_RETRY. dag_id=text_processing_dag_2, task_id=process_text, execution_date=20240618T000000, start_date=20240625T045541, end_date=20240625T045543
[2024-06-25 04:55:43,043] {standard_task_runner.py:92} ERROR - Failed to execute job 171 for task process_text
Traceback (most recent call last):
  File "/home/airflow/.local/lib/python3.6/site-packages/airflow/task/task_runner/standard_task_runner.py", line 85, in _start_by_fork
    args.func(args, dag=self.dag)
  File "/home/airflow/.local/lib/python3.6/site-packages/airflow/cli/cli_parser.py", line 48, in command
    return func(*args, **kwargs)
  File "/home/airflow/.local/lib/python3.6/site-packages/airflow/utils/cli.py", line 92, in wrapper
    return f(*args, **kwargs)
  File "/home/airflow/.local/lib/python3.6/site-packages/airflow/cli/commands/task_command.py", line 298, in task_run
    _run_task_by_selected_method(args, dag, ti)
  File "/home/airflow/.local/lib/python3.6/site-packages/airflow/cli/commands/task_command.py", line 107, in _run_task_by_selected_method
    _run_raw_task(args, ti)
  File "/home/airflow/.local/lib/python3.6/site-packages/airflow/cli/commands/task_command.py", line 184, in _run_raw_task
    error_file=args.error_file,
  File "/home/airflow/.local/lib/python3.6/site-packages/airflow/utils/session.py", line 70, in wrapper
    return func(*args, session=session, **kwargs)
  File "/home/airflow/.local/lib/python3.6/site-packages/airflow/models/taskinstance.py", line 1334, in _run_raw_task
    self._execute_task_with_callbacks(context)
  File "/home/airflow/.local/lib/python3.6/site-packages/airflow/models/taskinstance.py", line 1460, in _execute_task_with_callbacks
    result = self._execute_task(context, self.task)
  File "/home/airflow/.local/lib/python3.6/site-packages/airflow/models/taskinstance.py", line 1516, in _execute_task
    result = execute_callable(context=context)
  File "/home/airflow/.local/lib/python3.6/site-packages/airflow/operators/python.py", line 174, in execute
    return_value = self.execute_callable()
  File "/home/airflow/.local/lib/python3.6/site-packages/airflow/operators/python.py", line 188, in execute_callable
    return self.python_callable(*self.op_args, **self.op_kwargs)
  File "/opt/airflow/dags/../scripts/text_processing.py", line 19, in process_text
    df = pd.read_csv(input_path)
  File "/home/airflow/.local/lib/python3.6/site-packages/pandas/io/parsers.py", line 688, in read_csv
    return _read(filepath_or_buffer, kwds)
  File "/home/airflow/.local/lib/python3.6/site-packages/pandas/io/parsers.py", line 454, in _read
    parser = TextFileReader(fp_or_buf, **kwds)
  File "/home/airflow/.local/lib/python3.6/site-packages/pandas/io/parsers.py", line 948, in __init__
    self._make_engine(self.engine)
  File "/home/airflow/.local/lib/python3.6/site-packages/pandas/io/parsers.py", line 1180, in _make_engine
    self._engine = CParserWrapper(self.f, **self.options)
  File "/home/airflow/.local/lib/python3.6/site-packages/pandas/io/parsers.py", line 2010, in __init__
    self._reader = parsers.TextReader(src, **kwds)
  File "pandas/_libs/parsers.pyx", line 382, in pandas._libs.parsers.TextReader.__cinit__
  File "pandas/_libs/parsers.pyx", line 674, in pandas._libs.parsers.TextReader._setup_parser_source
FileNotFoundError: [Errno 2] No such file or directory: '/opt/airflow/data/processed_data_1.json'
[2024-06-25 04:55:43,071] {local_task_job.py:154} INFO - Task exited with return code 1
[2024-06-25 04:55:43,125] {local_task_job.py:264} INFO - 0 downstream tasks scheduled from follow-on schedule check
[2024-07-12 00:26:36,139] {taskinstance.py:1037} INFO - Dependencies all met for <TaskInstance: text_processing_dag_2.process_text scheduled__2024-06-18T00:00:00+00:00 [queued]>
[2024-07-12 00:26:36,150] {taskinstance.py:1037} INFO - Dependencies all met for <TaskInstance: text_processing_dag_2.process_text scheduled__2024-06-18T00:00:00+00:00 [queued]>
[2024-07-12 00:26:36,151] {taskinstance.py:1243} INFO - 
--------------------------------------------------------------------------------
[2024-07-12 00:26:36,151] {taskinstance.py:1244} INFO - Starting attempt 1 of 2
[2024-07-12 00:26:36,151] {taskinstance.py:1245} INFO - 
--------------------------------------------------------------------------------
[2024-07-12 00:26:36,163] {taskinstance.py:1264} INFO - Executing <Task(PythonOperator): process_text> on 2024-06-18 00:00:00+00:00
[2024-07-12 00:26:36,168] {standard_task_runner.py:52} INFO - Started process 4595 to run task
[2024-07-12 00:26:36,172] {standard_task_runner.py:76} INFO - Running: ['airflow', 'tasks', 'run', 'text_processing_dag_2', 'process_text', 'scheduled__2024-06-18T00:00:00+00:00', '--job-id', '3178', '--raw', '--subdir', 'DAGS_FOLDER/dag_text_processing_2.py', '--cfg-path', '/tmp/tmpp2_x2vc_', '--error-file', '/tmp/tmpqr9bi4n6']
[2024-07-12 00:26:36,176] {standard_task_runner.py:77} INFO - Job 3178: Subtask process_text
[2024-07-12 00:26:36,238] {logging_mixin.py:109} INFO - Running <TaskInstance: text_processing_dag_2.process_text scheduled__2024-06-18T00:00:00+00:00 [running]> on host cf249bbdc0d0
[2024-07-12 00:26:36,303] {taskinstance.py:1431} INFO - Exporting the following env vars:
AIRFLOW_CTX_DAG_OWNER=airflow
AIRFLOW_CTX_DAG_ID=text_processing_dag_2
AIRFLOW_CTX_TASK_ID=process_text
AIRFLOW_CTX_EXECUTION_DATE=2024-06-18T00:00:00+00:00
AIRFLOW_CTX_DAG_RUN_ID=scheduled__2024-06-18T00:00:00+00:00
[2024-07-12 00:26:37,069] {logging_mixin.py:109} INFO - Index(['date', 'time', 'messages', 'video_links', 'video_durations',
       'cleaned_text_entities', 'title', 'matched_city', 'combined_text',
       'summarized', 'matched_city2', 'city_result', 'latitude', 'longitude'],
      dtype='object')
[2024-07-12 00:27:04,382] {logging_mixin.py:109} INFO - Processed data saved to /opt/airflow/data/processed_data_2.json
[2024-07-12 00:27:04,388] {python.py:175} INFO - Done. Returned value was: None
[2024-07-12 00:27:04,524] {taskinstance.py:1282} INFO - Marking task as SUCCESS. dag_id=text_processing_dag_2, task_id=process_text, execution_date=20240618T000000, start_date=20240712T002636, end_date=20240712T002704
[2024-07-12 00:27:04,821] {local_task_job.py:154} INFO - Task exited with return code 0
[2024-07-12 00:27:04,939] {local_task_job.py:264} INFO - 0 downstream tasks scheduled from follow-on schedule check
[2024-07-12 00:28:46,451] {taskinstance.py:1037} INFO - Dependencies all met for <TaskInstance: text_processing_dag_2.process_text scheduled__2024-06-18T00:00:00+00:00 [queued]>
[2024-07-12 00:28:46,488] {taskinstance.py:1037} INFO - Dependencies all met for <TaskInstance: text_processing_dag_2.process_text scheduled__2024-06-18T00:00:00+00:00 [queued]>
[2024-07-12 00:28:46,489] {taskinstance.py:1243} INFO - 
--------------------------------------------------------------------------------
[2024-07-12 00:28:46,489] {taskinstance.py:1244} INFO - Starting attempt 1 of 2
[2024-07-12 00:28:46,489] {taskinstance.py:1245} INFO - 
--------------------------------------------------------------------------------
[2024-07-12 00:28:46,547] {taskinstance.py:1264} INFO - Executing <Task(PythonOperator): process_text> on 2024-06-18 00:00:00+00:00
[2024-07-12 00:28:46,585] {standard_task_runner.py:76} INFO - Running: ['airflow', 'tasks', 'run', 'text_processing_dag_2', 'process_text', 'scheduled__2024-06-18T00:00:00+00:00', '--job-id', '3217', '--raw', '--subdir', 'DAGS_FOLDER/dag_text_processing_2.py', '--cfg-path', '/tmp/tmpkqy15f6v', '--error-file', '/tmp/tmpoqfv4rcl']
[2024-07-12 00:28:46,591] {standard_task_runner.py:77} INFO - Job 3217: Subtask process_text
[2024-07-12 00:28:46,579] {standard_task_runner.py:52} INFO - Started process 4851 to run task
[2024-07-12 00:28:46,695] {logging_mixin.py:109} INFO - Running <TaskInstance: text_processing_dag_2.process_text scheduled__2024-06-18T00:00:00+00:00 [running]> on host cf249bbdc0d0
[2024-07-12 00:28:46,779] {taskinstance.py:1431} INFO - Exporting the following env vars:
AIRFLOW_CTX_DAG_OWNER=airflow
AIRFLOW_CTX_DAG_ID=text_processing_dag_2
AIRFLOW_CTX_TASK_ID=process_text
AIRFLOW_CTX_EXECUTION_DATE=2024-06-18T00:00:00+00:00
AIRFLOW_CTX_DAG_RUN_ID=scheduled__2024-06-18T00:00:00+00:00
[2024-07-12 00:28:47,817] {logging_mixin.py:109} INFO - Index(['date', 'time', 'messages', 'video_links', 'video_durations',
       'cleaned_text_entities', 'title', 'matched_city', 'combined_text',
       'summarized', 'matched_city2', 'city_result', 'latitude', 'longitude'],
      dtype='object')
[2024-07-12 00:29:06,871] {local_task_job.py:212} WARNING - State of this instance has been externally set to None. Terminating instance.
[2024-07-12 00:29:06,877] {process_utils.py:124} INFO - Sending Signals.SIGTERM to group 4851. PIDs of all processes in the group: [4851]
[2024-07-12 00:29:06,877] {process_utils.py:75} INFO - Sending the signal Signals.SIGTERM to group 4851
[2024-07-12 00:29:06,877] {taskinstance.py:1413} ERROR - Received SIGTERM. Terminating subprocesses.
[2024-07-12 00:29:06,877] {logging_mixin.py:109} INFO - Error fetching data for city: gaza+city, Error: Task received SIGTERM signal
[2024-07-12 00:29:07,841] {logging_mixin.py:109} INFO - Processed data saved to /opt/airflow/data/processed_data_2.json
[2024-07-12 00:29:07,846] {python.py:175} INFO - Done. Returned value was: None
[2024-07-12 00:29:07,879] {taskinstance.py:1282} INFO - Marking task as SUCCESS. dag_id=text_processing_dag_2, task_id=process_text, execution_date=20240618T000000, start_date=20240712T002846, end_date=20240712T002907
[2024-07-12 00:29:07,921] {process_utils.py:70} INFO - Process psutil.Process(pid=4851, status='terminated', exitcode=0, started='00:28:46') (4851) terminated with exit code 0
[2024-07-12 00:29:49,103] {taskinstance.py:1037} INFO - Dependencies all met for <TaskInstance: text_processing_dag_2.process_text scheduled__2024-06-18T00:00:00+00:00 [queued]>
[2024-07-12 00:29:49,117] {taskinstance.py:1037} INFO - Dependencies all met for <TaskInstance: text_processing_dag_2.process_text scheduled__2024-06-18T00:00:00+00:00 [queued]>
[2024-07-12 00:29:49,117] {taskinstance.py:1243} INFO - 
--------------------------------------------------------------------------------
[2024-07-12 00:29:49,117] {taskinstance.py:1244} INFO - Starting attempt 1 of 2
[2024-07-12 00:29:49,117] {taskinstance.py:1245} INFO - 
--------------------------------------------------------------------------------
[2024-07-12 00:29:49,132] {taskinstance.py:1264} INFO - Executing <Task(PythonOperator): process_text> on 2024-06-18 00:00:00+00:00
[2024-07-12 00:29:49,146] {standard_task_runner.py:52} INFO - Started process 4951 to run task
[2024-07-12 00:29:49,152] {standard_task_runner.py:76} INFO - Running: ['airflow', 'tasks', 'run', 'text_processing_dag_2', 'process_text', 'scheduled__2024-06-18T00:00:00+00:00', '--job-id', '3227', '--raw', '--subdir', 'DAGS_FOLDER/dag_text_processing_2.py', '--cfg-path', '/tmp/tmp_cebh3yv', '--error-file', '/tmp/tmpcf4kvgtp']
[2024-07-12 00:29:49,159] {standard_task_runner.py:77} INFO - Job 3227: Subtask process_text
[2024-07-12 00:29:49,226] {logging_mixin.py:109} INFO - Running <TaskInstance: text_processing_dag_2.process_text scheduled__2024-06-18T00:00:00+00:00 [running]> on host cf249bbdc0d0
[2024-07-12 00:29:49,296] {taskinstance.py:1431} INFO - Exporting the following env vars:
AIRFLOW_CTX_DAG_OWNER=airflow
AIRFLOW_CTX_DAG_ID=text_processing_dag_2
AIRFLOW_CTX_TASK_ID=process_text
AIRFLOW_CTX_EXECUTION_DATE=2024-06-18T00:00:00+00:00
AIRFLOW_CTX_DAG_RUN_ID=scheduled__2024-06-18T00:00:00+00:00
[2024-07-12 00:29:50,047] {logging_mixin.py:109} INFO - Index(['date', 'time', 'messages', 'video_links', 'video_durations',
       'cleaned_text_entities', 'title', 'matched_city', 'combined_text',
       'summarized', 'matched_city2', 'city_result', 'latitude', 'longitude'],
      dtype='object')
[2024-07-12 00:30:07,087] {logging_mixin.py:109} INFO - Processed data saved to /opt/airflow/data/processed_data_2.json
[2024-07-12 00:30:07,088] {python.py:175} INFO - Done. Returned value was: None
[2024-07-12 00:30:07,103] {taskinstance.py:1282} INFO - Marking task as SUCCESS. dag_id=text_processing_dag_2, task_id=process_text, execution_date=20240618T000000, start_date=20240712T002949, end_date=20240712T003007
[2024-07-12 00:30:07,155] {local_task_job.py:154} INFO - Task exited with return code 0
[2024-07-12 00:30:07,261] {local_task_job.py:264} INFO - 0 downstream tasks scheduled from follow-on schedule check
