[2024-06-20 19:37:28,580] {taskinstance.py:1037} INFO - Dependencies all met for <TaskInstance: text_processing_dag_2.process_text scheduled__2024-06-18T00:00:00+00:00 [queued]>
[2024-06-20 19:37:28,604] {taskinstance.py:1037} INFO - Dependencies all met for <TaskInstance: text_processing_dag_2.process_text scheduled__2024-06-18T00:00:00+00:00 [queued]>
[2024-06-20 19:37:28,605] {taskinstance.py:1243} INFO - 
--------------------------------------------------------------------------------
[2024-06-20 19:37:28,606] {taskinstance.py:1244} INFO - Starting attempt 2 of 2
[2024-06-20 19:37:28,607] {taskinstance.py:1245} INFO - 
--------------------------------------------------------------------------------
[2024-06-20 19:37:28,648] {taskinstance.py:1264} INFO - Executing <Task(PythonOperator): process_text> on 2024-06-18 00:00:00+00:00
[2024-06-20 19:37:28,654] {standard_task_runner.py:52} INFO - Started process 488 to run task
[2024-06-20 19:37:28,680] {standard_task_runner.py:76} INFO - Running: ['airflow', 'tasks', 'run', 'text_processing_dag_2', 'process_text', 'scheduled__2024-06-18T00:00:00+00:00', '--job-id', '20', '--raw', '--subdir', 'DAGS_FOLDER/dag_text_processing_2.py', '--cfg-path', '/tmp/tmpqxml5t_b', '--error-file', '/tmp/tmp4wxmpgbs']
[2024-06-20 19:37:28,684] {standard_task_runner.py:77} INFO - Job 20: Subtask process_text
[2024-06-20 19:37:28,787] {logging_mixin.py:109} INFO - Running <TaskInstance: text_processing_dag_2.process_text scheduled__2024-06-18T00:00:00+00:00 [running]> on host 09fa9687a8d2
[2024-06-20 19:37:28,861] {taskinstance.py:1431} INFO - Exporting the following env vars:
AIRFLOW_CTX_DAG_OWNER=airflow
AIRFLOW_CTX_DAG_ID=text_processing_dag_2
AIRFLOW_CTX_TASK_ID=process_text
AIRFLOW_CTX_EXECUTION_DATE=2024-06-18T00:00:00+00:00
AIRFLOW_CTX_DAG_RUN_ID=scheduled__2024-06-18T00:00:00+00:00
[2024-06-20 19:37:28,998] {taskinstance.py:1718} ERROR - Task failed with exception
Traceback (most recent call last):
  File "/home/airflow/.local/lib/python3.6/site-packages/airflow/models/taskinstance.py", line 1334, in _run_raw_task
    self._execute_task_with_callbacks(context)
  File "/home/airflow/.local/lib/python3.6/site-packages/airflow/models/taskinstance.py", line 1460, in _execute_task_with_callbacks
    result = self._execute_task(context, self.task)
  File "/home/airflow/.local/lib/python3.6/site-packages/airflow/models/taskinstance.py", line 1516, in _execute_task
    result = execute_callable(context=context)
  File "/home/airflow/.local/lib/python3.6/site-packages/airflow/operators/python.py", line 174, in execute
    return_value = self.execute_callable()
  File "/home/airflow/.local/lib/python3.6/site-packages/airflow/operators/python.py", line 188, in execute_callable
    return self.python_callable(*self.op_args, **self.op_kwargs)
  File "/opt/airflow/dags/../scripts/text_processing.py", line 16, in process_text
    nlp = spacy.load("en_core_web_sm")
  File "/home/airflow/.local/lib/python3.6/site-packages/spacy/__init__.py", line 57, in load
    config=config,
  File "/home/airflow/.local/lib/python3.6/site-packages/spacy/util.py", line 472, in load_model
    raise IOError(Errors.E050.format(name=name))
OSError: [E050] Can't find model 'en_core_web_sm'. It doesn't seem to be a Python package or a valid path to a data directory.
[2024-06-20 19:37:29,016] {taskinstance.py:1282} INFO - Marking task as FAILED. dag_id=text_processing_dag_2, task_id=process_text, execution_date=20240618T000000, start_date=20240620T193728, end_date=20240620T193729
[2024-06-20 19:37:29,032] {standard_task_runner.py:92} ERROR - Failed to execute job 20 for task process_text
Traceback (most recent call last):
  File "/home/airflow/.local/lib/python3.6/site-packages/airflow/task/task_runner/standard_task_runner.py", line 85, in _start_by_fork
    args.func(args, dag=self.dag)
  File "/home/airflow/.local/lib/python3.6/site-packages/airflow/cli/cli_parser.py", line 48, in command
    return func(*args, **kwargs)
  File "/home/airflow/.local/lib/python3.6/site-packages/airflow/utils/cli.py", line 92, in wrapper
    return f(*args, **kwargs)
  File "/home/airflow/.local/lib/python3.6/site-packages/airflow/cli/commands/task_command.py", line 298, in task_run
    _run_task_by_selected_method(args, dag, ti)
  File "/home/airflow/.local/lib/python3.6/site-packages/airflow/cli/commands/task_command.py", line 107, in _run_task_by_selected_method
    _run_raw_task(args, ti)
  File "/home/airflow/.local/lib/python3.6/site-packages/airflow/cli/commands/task_command.py", line 184, in _run_raw_task
    error_file=args.error_file,
  File "/home/airflow/.local/lib/python3.6/site-packages/airflow/utils/session.py", line 70, in wrapper
    return func(*args, session=session, **kwargs)
  File "/home/airflow/.local/lib/python3.6/site-packages/airflow/models/taskinstance.py", line 1334, in _run_raw_task
    self._execute_task_with_callbacks(context)
  File "/home/airflow/.local/lib/python3.6/site-packages/airflow/models/taskinstance.py", line 1460, in _execute_task_with_callbacks
    result = self._execute_task(context, self.task)
  File "/home/airflow/.local/lib/python3.6/site-packages/airflow/models/taskinstance.py", line 1516, in _execute_task
    result = execute_callable(context=context)
  File "/home/airflow/.local/lib/python3.6/site-packages/airflow/operators/python.py", line 174, in execute
    return_value = self.execute_callable()
  File "/home/airflow/.local/lib/python3.6/site-packages/airflow/operators/python.py", line 188, in execute_callable
    return self.python_callable(*self.op_args, **self.op_kwargs)
  File "/opt/airflow/dags/../scripts/text_processing.py", line 16, in process_text
    nlp = spacy.load("en_core_web_sm")
  File "/home/airflow/.local/lib/python3.6/site-packages/spacy/__init__.py", line 57, in load
    config=config,
  File "/home/airflow/.local/lib/python3.6/site-packages/spacy/util.py", line 472, in load_model
    raise IOError(Errors.E050.format(name=name))
OSError: [E050] Can't find model 'en_core_web_sm'. It doesn't seem to be a Python package or a valid path to a data directory.
[2024-06-20 19:37:29,054] {local_task_job.py:154} INFO - Task exited with return code 1
[2024-06-20 19:37:29,117] {local_task_job.py:264} INFO - 0 downstream tasks scheduled from follow-on schedule check
[2024-06-20 20:07:23,241] {taskinstance.py:1037} INFO - Dependencies all met for <TaskInstance: text_processing_dag_2.process_text scheduled__2024-06-18T00:00:00+00:00 [queued]>
[2024-06-20 20:07:23,256] {taskinstance.py:1037} INFO - Dependencies all met for <TaskInstance: text_processing_dag_2.process_text scheduled__2024-06-18T00:00:00+00:00 [queued]>
[2024-06-20 20:07:23,257] {taskinstance.py:1243} INFO - 
--------------------------------------------------------------------------------
[2024-06-20 20:07:23,257] {taskinstance.py:1244} INFO - Starting attempt 2 of 2
[2024-06-20 20:07:23,257] {taskinstance.py:1245} INFO - 
--------------------------------------------------------------------------------
[2024-06-20 20:07:23,270] {taskinstance.py:1264} INFO - Executing <Task(PythonOperator): process_text> on 2024-06-18 00:00:00+00:00
[2024-06-20 20:07:23,275] {standard_task_runner.py:52} INFO - Started process 563 to run task
[2024-06-20 20:07:23,280] {standard_task_runner.py:76} INFO - Running: ['airflow', 'tasks', 'run', 'text_processing_dag_2', 'process_text', 'scheduled__2024-06-18T00:00:00+00:00', '--job-id', '34', '--raw', '--subdir', 'DAGS_FOLDER/dag_text_processing_2.py', '--cfg-path', '/tmp/tmpi6isg0y5', '--error-file', '/tmp/tmph9317aiy']
[2024-06-20 20:07:23,284] {standard_task_runner.py:77} INFO - Job 34: Subtask process_text
[2024-06-20 20:07:23,371] {logging_mixin.py:109} INFO - Running <TaskInstance: text_processing_dag_2.process_text scheduled__2024-06-18T00:00:00+00:00 [running]> on host b95ccdd7ac61
[2024-06-20 20:07:23,448] {taskinstance.py:1431} INFO - Exporting the following env vars:
AIRFLOW_CTX_DAG_OWNER=airflow
AIRFLOW_CTX_DAG_ID=text_processing_dag_2
AIRFLOW_CTX_TASK_ID=process_text
AIRFLOW_CTX_EXECUTION_DATE=2024-06-18T00:00:00+00:00
AIRFLOW_CTX_DAG_RUN_ID=scheduled__2024-06-18T00:00:00+00:00
[2024-06-20 20:07:23,543] {taskinstance.py:1718} ERROR - Task failed with exception
Traceback (most recent call last):
  File "/home/airflow/.local/lib/python3.6/site-packages/airflow/models/taskinstance.py", line 1334, in _run_raw_task
    self._execute_task_with_callbacks(context)
  File "/home/airflow/.local/lib/python3.6/site-packages/airflow/models/taskinstance.py", line 1460, in _execute_task_with_callbacks
    result = self._execute_task(context, self.task)
  File "/home/airflow/.local/lib/python3.6/site-packages/airflow/models/taskinstance.py", line 1516, in _execute_task
    result = execute_callable(context=context)
  File "/home/airflow/.local/lib/python3.6/site-packages/airflow/operators/python.py", line 174, in execute
    return_value = self.execute_callable()
  File "/home/airflow/.local/lib/python3.6/site-packages/airflow/operators/python.py", line 188, in execute_callable
    return self.python_callable(*self.op_args, **self.op_kwargs)
  File "/opt/airflow/dags/../scripts/text_processing.py", line 16, in process_text
    nlp = spacy.load("en_core_web_sm")
  File "/home/airflow/.local/lib/python3.6/site-packages/spacy/__init__.py", line 57, in load
    config=config,
  File "/home/airflow/.local/lib/python3.6/site-packages/spacy/util.py", line 472, in load_model
    raise IOError(Errors.E050.format(name=name))
OSError: [E050] Can't find model 'en_core_web_sm'. It doesn't seem to be a Python package or a valid path to a data directory.
[2024-06-20 20:07:23,561] {taskinstance.py:1282} INFO - Marking task as FAILED. dag_id=text_processing_dag_2, task_id=process_text, execution_date=20240618T000000, start_date=20240620T200723, end_date=20240620T200723
[2024-06-20 20:07:23,575] {standard_task_runner.py:92} ERROR - Failed to execute job 34 for task process_text
Traceback (most recent call last):
  File "/home/airflow/.local/lib/python3.6/site-packages/airflow/task/task_runner/standard_task_runner.py", line 85, in _start_by_fork
    args.func(args, dag=self.dag)
  File "/home/airflow/.local/lib/python3.6/site-packages/airflow/cli/cli_parser.py", line 48, in command
    return func(*args, **kwargs)
  File "/home/airflow/.local/lib/python3.6/site-packages/airflow/utils/cli.py", line 92, in wrapper
    return f(*args, **kwargs)
  File "/home/airflow/.local/lib/python3.6/site-packages/airflow/cli/commands/task_command.py", line 298, in task_run
    _run_task_by_selected_method(args, dag, ti)
  File "/home/airflow/.local/lib/python3.6/site-packages/airflow/cli/commands/task_command.py", line 107, in _run_task_by_selected_method
    _run_raw_task(args, ti)
  File "/home/airflow/.local/lib/python3.6/site-packages/airflow/cli/commands/task_command.py", line 184, in _run_raw_task
    error_file=args.error_file,
  File "/home/airflow/.local/lib/python3.6/site-packages/airflow/utils/session.py", line 70, in wrapper
    return func(*args, session=session, **kwargs)
  File "/home/airflow/.local/lib/python3.6/site-packages/airflow/models/taskinstance.py", line 1334, in _run_raw_task
    self._execute_task_with_callbacks(context)
  File "/home/airflow/.local/lib/python3.6/site-packages/airflow/models/taskinstance.py", line 1460, in _execute_task_with_callbacks
    result = self._execute_task(context, self.task)
  File "/home/airflow/.local/lib/python3.6/site-packages/airflow/models/taskinstance.py", line 1516, in _execute_task
    result = execute_callable(context=context)
  File "/home/airflow/.local/lib/python3.6/site-packages/airflow/operators/python.py", line 174, in execute
    return_value = self.execute_callable()
  File "/home/airflow/.local/lib/python3.6/site-packages/airflow/operators/python.py", line 188, in execute_callable
    return self.python_callable(*self.op_args, **self.op_kwargs)
  File "/opt/airflow/dags/../scripts/text_processing.py", line 16, in process_text
    nlp = spacy.load("en_core_web_sm")
  File "/home/airflow/.local/lib/python3.6/site-packages/spacy/__init__.py", line 57, in load
    config=config,
  File "/home/airflow/.local/lib/python3.6/site-packages/spacy/util.py", line 472, in load_model
    raise IOError(Errors.E050.format(name=name))
OSError: [E050] Can't find model 'en_core_web_sm'. It doesn't seem to be a Python package or a valid path to a data directory.
[2024-06-20 20:07:23,616] {local_task_job.py:154} INFO - Task exited with return code 1
[2024-06-20 20:07:23,662] {local_task_job.py:264} INFO - 0 downstream tasks scheduled from follow-on schedule check
[2024-06-21 06:38:07,209] {taskinstance.py:1037} INFO - Dependencies all met for <TaskInstance: text_processing_dag_2.process_text scheduled__2024-06-18T00:00:00+00:00 [queued]>
[2024-06-21 06:38:07,223] {taskinstance.py:1037} INFO - Dependencies all met for <TaskInstance: text_processing_dag_2.process_text scheduled__2024-06-18T00:00:00+00:00 [queued]>
[2024-06-21 06:38:07,223] {taskinstance.py:1243} INFO - 
--------------------------------------------------------------------------------
[2024-06-21 06:38:07,223] {taskinstance.py:1244} INFO - Starting attempt 2 of 2
[2024-06-21 06:38:07,223] {taskinstance.py:1245} INFO - 
--------------------------------------------------------------------------------
[2024-06-21 06:38:07,234] {taskinstance.py:1264} INFO - Executing <Task(PythonOperator): process_text> on 2024-06-18 00:00:00+00:00
[2024-06-21 06:38:07,238] {standard_task_runner.py:52} INFO - Started process 487 to run task
[2024-06-21 06:38:07,243] {standard_task_runner.py:76} INFO - Running: ['airflow', 'tasks', 'run', 'text_processing_dag_2', 'process_text', 'scheduled__2024-06-18T00:00:00+00:00', '--job-id', '88', '--raw', '--subdir', 'DAGS_FOLDER/dag_text_processing_2.py', '--cfg-path', '/tmp/tmp7lugawcc', '--error-file', '/tmp/tmppx5ek1ou']
[2024-06-21 06:38:07,246] {standard_task_runner.py:77} INFO - Job 88: Subtask process_text
[2024-06-21 06:38:07,314] {logging_mixin.py:109} INFO - Running <TaskInstance: text_processing_dag_2.process_text scheduled__2024-06-18T00:00:00+00:00 [running]> on host 95c89469de59
[2024-06-21 06:38:07,415] {taskinstance.py:1431} INFO - Exporting the following env vars:
AIRFLOW_CTX_DAG_OWNER=airflow
AIRFLOW_CTX_DAG_ID=text_processing_dag_2
AIRFLOW_CTX_TASK_ID=process_text
AIRFLOW_CTX_EXECUTION_DATE=2024-06-18T00:00:00+00:00
AIRFLOW_CTX_DAG_RUN_ID=scheduled__2024-06-18T00:00:00+00:00
[2024-06-21 06:38:14,583] {logging_mixin.py:109} INFO - Processed data saved to /opt/airflow/data/processed_data_2.json
[2024-06-21 06:38:14,585] {python.py:175} INFO - Done. Returned value was: None
[2024-06-21 06:38:14,601] {taskinstance.py:1282} INFO - Marking task as SUCCESS. dag_id=text_processing_dag_2, task_id=process_text, execution_date=20240618T000000, start_date=20240621T063807, end_date=20240621T063814
[2024-06-21 06:38:14,662] {local_task_job.py:154} INFO - Task exited with return code 0
[2024-06-21 06:38:14,699] {local_task_job.py:264} INFO - 0 downstream tasks scheduled from follow-on schedule check
[2024-06-25 05:00:45,764] {taskinstance.py:1037} INFO - Dependencies all met for <TaskInstance: text_processing_dag_2.process_text scheduled__2024-06-18T00:00:00+00:00 [queued]>
[2024-06-25 05:00:45,781] {taskinstance.py:1037} INFO - Dependencies all met for <TaskInstance: text_processing_dag_2.process_text scheduled__2024-06-18T00:00:00+00:00 [queued]>
[2024-06-25 05:00:45,782] {taskinstance.py:1243} INFO - 
--------------------------------------------------------------------------------
[2024-06-25 05:00:45,782] {taskinstance.py:1244} INFO - Starting attempt 2 of 2
[2024-06-25 05:00:45,782] {taskinstance.py:1245} INFO - 
--------------------------------------------------------------------------------
[2024-06-25 05:00:45,798] {taskinstance.py:1264} INFO - Executing <Task(PythonOperator): process_text> on 2024-06-18 00:00:00+00:00
[2024-06-25 05:00:45,804] {standard_task_runner.py:52} INFO - Started process 3782 to run task
[2024-06-25 05:00:45,816] {standard_task_runner.py:76} INFO - Running: ['airflow', 'tasks', 'run', 'text_processing_dag_2', 'process_text', 'scheduled__2024-06-18T00:00:00+00:00', '--job-id', '177', '--raw', '--subdir', 'DAGS_FOLDER/dag_text_processing_2.py', '--cfg-path', '/tmp/tmp4uqg5dc9', '--error-file', '/tmp/tmpdx0ilw_y']
[2024-06-25 05:00:45,825] {standard_task_runner.py:77} INFO - Job 177: Subtask process_text
[2024-06-25 05:00:45,926] {logging_mixin.py:109} INFO - Running <TaskInstance: text_processing_dag_2.process_text scheduled__2024-06-18T00:00:00+00:00 [running]> on host 09709d0d4538
[2024-06-25 05:00:46,010] {taskinstance.py:1431} INFO - Exporting the following env vars:
AIRFLOW_CTX_DAG_OWNER=airflow
AIRFLOW_CTX_DAG_ID=text_processing_dag_2
AIRFLOW_CTX_TASK_ID=process_text
AIRFLOW_CTX_EXECUTION_DATE=2024-06-18T00:00:00+00:00
AIRFLOW_CTX_DAG_RUN_ID=scheduled__2024-06-18T00:00:00+00:00
[2024-06-25 05:00:46,860] {taskinstance.py:1718} ERROR - Task failed with exception
Traceback (most recent call last):
  File "/home/airflow/.local/lib/python3.6/site-packages/airflow/models/taskinstance.py", line 1334, in _run_raw_task
    self._execute_task_with_callbacks(context)
  File "/home/airflow/.local/lib/python3.6/site-packages/airflow/models/taskinstance.py", line 1460, in _execute_task_with_callbacks
    result = self._execute_task(context, self.task)
  File "/home/airflow/.local/lib/python3.6/site-packages/airflow/models/taskinstance.py", line 1516, in _execute_task
    result = execute_callable(context=context)
  File "/home/airflow/.local/lib/python3.6/site-packages/airflow/operators/python.py", line 174, in execute
    return_value = self.execute_callable()
  File "/home/airflow/.local/lib/python3.6/site-packages/airflow/operators/python.py", line 188, in execute_callable
    return self.python_callable(*self.op_args, **self.op_kwargs)
  File "/opt/airflow/dags/../scripts/text_processing.py", line 19, in process_text
    df = pd.read_csv(input_path)
  File "/home/airflow/.local/lib/python3.6/site-packages/pandas/io/parsers.py", line 688, in read_csv
    return _read(filepath_or_buffer, kwds)
  File "/home/airflow/.local/lib/python3.6/site-packages/pandas/io/parsers.py", line 460, in _read
    data = parser.read(nrows)
  File "/home/airflow/.local/lib/python3.6/site-packages/pandas/io/parsers.py", line 1198, in read
    ret = self._engine.read(nrows)
  File "/home/airflow/.local/lib/python3.6/site-packages/pandas/io/parsers.py", line 2157, in read
    data = self._reader.read(nrows)
  File "pandas/_libs/parsers.pyx", line 847, in pandas._libs.parsers.TextReader.read
  File "pandas/_libs/parsers.pyx", line 862, in pandas._libs.parsers.TextReader._read_low_memory
  File "pandas/_libs/parsers.pyx", line 918, in pandas._libs.parsers.TextReader._read_rows
  File "pandas/_libs/parsers.pyx", line 905, in pandas._libs.parsers.TextReader._tokenize_rows
  File "pandas/_libs/parsers.pyx", line 2042, in pandas._libs.parsers.raise_parser_error
pandas.errors.ParserError: Error tokenizing data. C error: Expected 32 fields in line 3, saw 53

[2024-06-25 05:00:46,921] {taskinstance.py:1282} INFO - Marking task as FAILED. dag_id=text_processing_dag_2, task_id=process_text, execution_date=20240618T000000, start_date=20240625T050045, end_date=20240625T050046
[2024-06-25 05:00:46,943] {standard_task_runner.py:92} ERROR - Failed to execute job 177 for task process_text
Traceback (most recent call last):
  File "/home/airflow/.local/lib/python3.6/site-packages/airflow/task/task_runner/standard_task_runner.py", line 85, in _start_by_fork
    args.func(args, dag=self.dag)
  File "/home/airflow/.local/lib/python3.6/site-packages/airflow/cli/cli_parser.py", line 48, in command
    return func(*args, **kwargs)
  File "/home/airflow/.local/lib/python3.6/site-packages/airflow/utils/cli.py", line 92, in wrapper
    return f(*args, **kwargs)
  File "/home/airflow/.local/lib/python3.6/site-packages/airflow/cli/commands/task_command.py", line 298, in task_run
    _run_task_by_selected_method(args, dag, ti)
  File "/home/airflow/.local/lib/python3.6/site-packages/airflow/cli/commands/task_command.py", line 107, in _run_task_by_selected_method
    _run_raw_task(args, ti)
  File "/home/airflow/.local/lib/python3.6/site-packages/airflow/cli/commands/task_command.py", line 184, in _run_raw_task
    error_file=args.error_file,
  File "/home/airflow/.local/lib/python3.6/site-packages/airflow/utils/session.py", line 70, in wrapper
    return func(*args, session=session, **kwargs)
  File "/home/airflow/.local/lib/python3.6/site-packages/airflow/models/taskinstance.py", line 1334, in _run_raw_task
    self._execute_task_with_callbacks(context)
  File "/home/airflow/.local/lib/python3.6/site-packages/airflow/models/taskinstance.py", line 1460, in _execute_task_with_callbacks
    result = self._execute_task(context, self.task)
  File "/home/airflow/.local/lib/python3.6/site-packages/airflow/models/taskinstance.py", line 1516, in _execute_task
    result = execute_callable(context=context)
  File "/home/airflow/.local/lib/python3.6/site-packages/airflow/operators/python.py", line 174, in execute
    return_value = self.execute_callable()
  File "/home/airflow/.local/lib/python3.6/site-packages/airflow/operators/python.py", line 188, in execute_callable
    return self.python_callable(*self.op_args, **self.op_kwargs)
  File "/opt/airflow/dags/../scripts/text_processing.py", line 19, in process_text
    df = pd.read_csv(input_path)
  File "/home/airflow/.local/lib/python3.6/site-packages/pandas/io/parsers.py", line 688, in read_csv
    return _read(filepath_or_buffer, kwds)
  File "/home/airflow/.local/lib/python3.6/site-packages/pandas/io/parsers.py", line 460, in _read
    data = parser.read(nrows)
  File "/home/airflow/.local/lib/python3.6/site-packages/pandas/io/parsers.py", line 1198, in read
    ret = self._engine.read(nrows)
  File "/home/airflow/.local/lib/python3.6/site-packages/pandas/io/parsers.py", line 2157, in read
    data = self._reader.read(nrows)
  File "pandas/_libs/parsers.pyx", line 847, in pandas._libs.parsers.TextReader.read
  File "pandas/_libs/parsers.pyx", line 862, in pandas._libs.parsers.TextReader._read_low_memory
  File "pandas/_libs/parsers.pyx", line 918, in pandas._libs.parsers.TextReader._read_rows
  File "pandas/_libs/parsers.pyx", line 905, in pandas._libs.parsers.TextReader._tokenize_rows
  File "pandas/_libs/parsers.pyx", line 2042, in pandas._libs.parsers.raise_parser_error
pandas.errors.ParserError: Error tokenizing data. C error: Expected 32 fields in line 3, saw 53

[2024-06-25 05:00:46,981] {local_task_job.py:154} INFO - Task exited with return code 1
[2024-06-25 05:00:47,030] {local_task_job.py:264} INFO - 0 downstream tasks scheduled from follow-on schedule check
